Workbook

Sheet BẢNG TỔNG HỢP
A1: PHỤ LỤC 2:
A2: BẢNG TỔNG HỢP NHU CẦU CÁP QUANG PON CÁC ĐƠN VỊ 2026
A3: (Kèm theo văn bản số 114/CV-HT ngày 02 tháng 03 năm 2026)
A5: STT | B5: SITE | C5: TỔ HT | D5: KHU VỰC TTVT | E5: Cáp quang 6FO(m) | F5: Cáp quang 12FO(m) | G5: SP 1:4 | H5: SP 1: 8 (S1) | I5: SP 1: 8 (S2) | J5: SP 1: 16 | K5: TỔNG CÁP NHU CẦU | L5: GHI CHÚ | R5: 2025
A6: TỔNG CỘNG(I+II): | E6: =E13 -> 80000 | F6: =F13 -> 0 | G6: =G13 -> 111 | H6: =H13 -> 0 | I6: =I13 -> 0 | J6: =J13 -> 417 | K6: =SUM(E6:F6) -> 80000
A7: 1 | B7: LONG XUYÊN | C7: An Châu | D7: An Châu | E7: =ACU_OK!K3 -> 15000 | F7: =ACU_OK!L3 -> 0 | G7: =ACU_OK!N3 -> 22 | H7: =ACU_OK!O3 -> 0 | I7: =ACU_OK!P3 -> 0 | J7: =ACU_OK!Q3 -> 87 | K7: =SUM(E7:F7) -> 15000
A8: 2 | D8: Châu Phú | E8: =CPU_OK!K3 -> 18000 | F8: =CPU_OK!L3 -> 0 | G8: =CPU_OK!N3 -> 21 | H8: =CPU_OK!O3 -> 0 | I8: =CPU_OK!P3 -> 0 | J8: =CPU_OK!Q3 -> 84 | K8: =SUM(E8:F8) -> 18000
A9: 3 | C9: Châu Đốc | D9: An Phú | E9: =APU_OK!K3 -> 17000 | F9: =APU_OK!L3 -> 0 | G9: =APU_OK!N3 -> 23 | H9: =APU_OK!O3 -> 0 | I9: =APU_OK!P3 -> 0 | J9: =APU_OK!Q3 -> 86 | K9: =SUM(E9:F9) -> 17000
A10: 4 | D10: Châu Đốc | E10: =CĐC_OK!K3 -> 12000 | F10: =CĐC_OK!L3 -> 0 | G10: =CĐC_OK!N3 -> 16 | H10: =CĐC_OK!O3 -> 0 | I10: =CĐC_OK!P3 -> 0 | J10: =CĐC_OK!Q3 -> 60 | K10: =SUM(E10:F10) -> 12000
A11: 8 | C11: Phú Tân | D11: Phú Tân | E11: =PTN_OK!K3 -> 10000 | F11: =PTN_OK!L3 -> 0 | G11: =PTN_OK!N3 -> 18 | H11: =PTN_OK!O3 -> 0 | I11: =PTN_OK!P3 -> 0 | J11: =PTN_OK!Q3 -> 61 | K11: =SUM(E11:F11) -> 10000
A12: 9 | D12: Tân Châu | E12: =TCU_OK!K3 -> 8000 | F12: =TCU_OK!L3 -> 0 | G12: =TCU_OK!N3 -> 11 | H12: =TCU_OK!O3 -> 0 | I12: =TCU_OK!P3 -> 0 | J12: =TCU_OK!Q3 -> 39 | K12: =SUM(E12:F12) -> 8000
A13: II. TỔNG SITE LONG XUYÊN | E13: =SUM(E7:E12) -> 80000 | F13: =SUM(F7:F12) -> 0 | G13: =SUM(G7:G12) -> 111 | H13: =SUM(H7:H12) -> 0 | I13: =SUM(I7:I12) -> 0 | J13: =SUM(J7:J12) -> 417 | K13: =SUM(E13:F13) -> 80000 | R13: 328

Sheet ACU_OK
B1: VTAG - TỔNG HỢP NHU CẦU CÁP QUANG GPON 2026
B3: TỔNG CỘNG: | I3: TTVT AN CHÂU | K3: =SUMIF($C$6:$C$4312,"An Châu",K6:K4312) -> 15000 | L3: =SUMIF($C$6:$C$4312,"An Châu",L6:L4312) -> 0 | M3: =SUMIF($C$6:$C$4312,"An Châu",M6:M4312) -> 0 | N3: =SUMIF($C$6:$C$4312,"An Châu",N6:N4312) -> 22 | O3: =SUMIF($C$6:$C$4312,"An Châu",O6:O4312) -> 0 | P3: =SUMIF($C$6:$C$4312,"An Châu",P6:P4312) -> 0 | Q3: =SUMIF($C$6:$C$4312,"An Châu",Q6:Q4312) -> 87 | R3: =SUMIF($C$6:$C$4312,"An Châu",R6:R4312) -> 6
A4: TUYẾN TỔNG HỢP | B4: STT | C4: Đơn vị | D4: OLT | E4: ĐIỂM ĐẦU A | F4: ĐIỂM ĐẦU B | G4: Tọa độ A | I4: Tọa độ B | K4: Cáp quang 6FO(m) | L4: Cáp quang 12FO(m) | M4: Cáp quang 24FO(m) | N4: SP 1:4 | O4: SP 1: 8 (S1) | P4: SP 1: 8 (S2) | Q4: SP 1: 16 | R4: ODF | S4: Ghi chú | T4: Thông tin bên Biểu 3_MẠNg GPON | U4: Mức độ Ưu tiên từ 1-3 | V4: TTHT CHECK
G5: Long | H5: lat | I5: Long | J5: lat | K5: =SUBTOTAL(9,K6:K3952) -> 15000 | L5: =SUBTOTAL(9,L6:L3952) -> 0 | M5: =SUBTOTAL(9,M6:M3952) -> 0 | N5: =SUBTOTAL(9,N6:N3952) -> 22 | O5: =SUBTOTAL(9,O6:O3952) -> 0 | P5: =SUBTOTAL(9,P6:P3952) -> 0 | Q5: =SUBTOTAL(9,Q6:Q3952) -> 87 | R5: =SUBTOTAL(9,R6:R3952) -> 6 | V5: KẾT QUẢ | W5: LÍ DO
A6: KDC nvc - KDC NVC 2 | B6: 1 | C6: An Châu | D6: CTH008 | E6: ODF 12FO Rạch Mương Trâu | F6: S2-VP ấp Bình Phú 2 | G6: 105.36028 | H6: 10.451609 | I6: 105.36076 | J6: 10.45062 | K6: 200 | N6: 1 | Q6: 1 | R6: 1 | T6: Tuyến BTS CTH040 - Cầu Mương Trâu | U6: 1 | V6: OK
A7: UBND XA CÔ TÔ - NGUYỄN THỊ SÁNG | B7: 2 | C7: An Châu | D7: CTH008 | E7: S2-VP ấp Bình Phú 2 | F7: S2-Ngang VP ấp Bình Phú 2 | G7: 105.36076 | H7: 10.45062 | I7: 105.36029 | J7: 10.45061 | K7: 100 | Q7: 1 | T7: Tuyến BTS CTH040 - Cầu Mương Trâu | U7: 1 | V7: OK
A8: UBND XA CÔ TÔ - NGUYỄN THỊ SÁNG | B8: 3 | C8: An Châu | D8: CTH008 | E8: S2-VP ấp Bình Phú 2 | F8: S2-Nhà trọ Minh Ánh | G8: 105.36076 | H8: 10.45062 | I8: 105.35981 | J8: 10.449189 | K8: 200 | Q8: 1 | T8: Tuyến BTS CTH040 - Cầu Mương Trâu | U8: 1 | V8: OK
A9: UBND XA CÔ TÔ - NGUYỄN THỊ SÁNG | B9: 4 | C9: An Châu | D9: CTH008 | E9: S2-Nhà trọ Minh Ánh | F9: S2-Trong nhà trọ Minh Ánh | G9: 105.35981 | H9: 10.449189 | I9: 105.35875 | J9: 10.44798 | K9: 200 | Q9: 1 | T9: Tuyến BTS CTH040 - Cầu Mương Trâu | U9: 1 | V9: OK
A10: UBND XA CÔ TÔ - NGUYỄN THỊ SÁNG | B10: 5 | C10: An Châu | D10: CTH008 | E10: ODF 12FO Bến tàu chợ Bình Hoà | F10: S2-Bến Tàu chợ Bình Hoà | G10: 105.34328 | H10: 10.46179 | I10: 105.33904 | J10: 10.462819 | K10: 650 | N10: 1 | Q10: 1 | R10: 1 | T10: Truyến BTS CTH008 - Bến tàu chợ Bình Hòa | U10: 1 | V10: OK | W10: Sửa toạ độ ODF 12FO Bến tàu chợ Bình Hoà
A11: UBND XA CÔ TÔ - NGUYỄN THỊ SÁNG | B11: 6 | C11: An Châu | D11: CTH008 | E11: S2-Bến Tàu chợ Bình Hoà | F11: S2-VTNN Minh Trí | G11: 105.33903 | H11: 10.462821 | I11: 105.33895 | J11: 10.461904 | Q11: 1 | S11: Lắp hộp Splitter trên tuyến cáp hiện hữu | T11: Truyến BTS CTH008 - Bến tàu chợ Bình Hòa | U11: 1 | V11: OK
A12: UBND XA CÔ TÔ - NGUYỄN THỊ SÁNG | B12: 7 | C12: An Châu | D12: CTH008 | E12: S2-VTNN Minh Trí | F12: S2-VLXD Út Chót | G12: 105.33895 | H12: 10.461904 | I12: 105.33826 | J12: 10.461231 | Q12: 1 | S12: Lắp hộp Splitter trên tuyến cáp hiện hữu | T12: Truyến BTS CTH008 - Bến tàu chợ Bình Hòa | U12: 1 | V12: OK
A13: UBND XA CÔ TÔ - NGUYỄN THỊ SÁNG | B13: 8 | C13: An Châu | D13: CTH008 | E13: S2-VLXD Út Chót | F13: S2-Bún cá Út Mỹ | G13: 105.33826 | H13: 10.461231 | I13: 105.33726 | J13: 10.460248 | Q13: 1 | S13: Lắp hộp Splitter trên tuyến cáp hiện hữu | T13: Truyến BTS CTH008 - Bến tàu chợ Bình Hòa | U13: 1 | V13: OK | W13: Sửa toạ độ điểm S2-Bún Cá Út Mỹ
A14: UBND XA CÔ TÔ - NGUYỄN THỊ SÁNG | B14: 9 | C14: An Châu | D14: CTH008 | E14: S2-Bún cá Út Mỹ | F14: S2-Ngoài Cấp 1 A Bình Hòa | G14: 105.33726 | H14: 10.460248 | I14: 105.33578 | J14: 10.459265 | N14: 1 | Q14: 1 | S14: Lắp hộp Splitter trên tuyến cáp hiện hữu | T14: Truyến BTS CTH008 - Bến tàu chợ Bình Hòa | U14: 1 | V14: OK
A15: UBND XA CÔ TÔ - NGUYỄN THỊ SÁNG | B15: 10 | C15: An Châu | D15: CTH008 | E15: S2-Ngoài Cấp 1 A Bình Hòa | F15: S2-Trong đình Bình Hòa | G15: 105.33578 | H15: 10.459265 | I15: 105.33428 | J15: 10.459191 | Q15: 1 | S15: Lắp hộp Splitter trên tuyến cáp hiện hữu | T15: Truyến BTS CTH008 - Bến tàu chợ Bình Hòa | U15: 1 | V15: OK
A16: TTO021 - TÂM SỬA XE HÀN TIỆN | B16: 11 | C16: An Châu | D16: CTH008 | E16: S2-Quảng cáo Đặng Lộc | F16: S2-Ngang Thái Khương | G16: 105.33349 | H16: 10.459326 | I16: 105.33268 | J16: 10.458551 | Q16: 1 | S16: Lắp hộp Splitter trên tuyến cáp hiện hữu | T16: Truyến BTS CTH008 - Bến tàu chợ Bình Hòa | U16: 1 | V16: OK
A17: TTO021 - TÂM SỬA XE HÀN TIỆN | B17: 12 | C17: An Châu | D17: CTH008 | E17: S2-Ngang Thái Khương | F17: S2-Tuấn Tú | G17: 105.33268 | H17: 10.458551 | I17: 105.33262 | J17: 10.457129 | Q17: 1 | S17: Lắp hộp Splitter trên tuyến cáp hiện hữu | T17: Truyến BTS CTH008 - Bến tàu chợ Bình Hòa | U17: 1 | V17: OK | W17: Phục vụ giảm tải cho tủ S2-AGG.CTH.BHA.OLT.A21.4.3.3
A18: TTO021 - TÂM SỬA XE HÀN TIỆN | B18: 13 | C18: An Châu | D18: CTH008 | E18: S2-Tuấn Tú | F18: S2-Trong Tuấn Tú | G18: 105.33262 | H18: 10.457129 | I18: 105.33187 | J18: 10.455513 | N18: 1 | Q18: 1 | S18: Lắp hộp Splitter trên tuyến cáp hiện hữu | T18: Truyến BTS CTH008 - Bến tàu chợ Bình Hòa | U18: 1 | V18: OK | W18: Sửa toạ độ S2-Trong Tuấn Tú
A19: TTO021 - TÂM SỬA XE HÀN TIỆN | B19: 14 | C19: An Châu | D19: CTH008 | E19: S2-Trong Tuấn Tú | F19: S2-Trong Anh Tài | G19: 105.33187 | H19: 10.455513 | I19: 105.33187 | J19: 10.454065 | Q19: 1 | S19: Lắp hộp Splitter trên tuyến cáp hiện hữu | T19: Truyến BTS CTH008 - Bến tàu chợ Bình Hòa | U19: 1 | V19: OK
A20: TTO021 - TÂM SỬA XE HÀN TIỆN | B20: 15 | C20: An Châu | D20: CTH008 | E20: S2-Trong Anh Tài | F20: S2-Trước CTH029 | G20: 105.33187 | H20: 10.454274 | I20: 105.33185 | J20: 10.451673 | Q20: 1 | S20: Lắp hộp Splitter trên tuyến cáp hiện hữu | T20: Truyến BTS CTH008 - Bến tàu chợ Bình Hòa | U20: 1 | V20: OK
A21: TTO021 - TÂM SỬA XE HÀN TIỆN | B21: 16 | C21: An Châu | D21: CTH008 | E21: S2-Trước CTH029 | F21: S2-Thiện Nhuận | G21: 105.33185 | H21: 10.451673 | I21: 105.33243 | J21: 10.449945 | Q21: 1 | S21: Lắp hộp Splitter trên tuyến cáp hiện hữu | T21: Truyến BTS CTH008 - Bến tàu chợ Bình Hòa | U21: 1 | V21: OK | W21: Sửa toạ độ S2-Thiện Nhuận
A22: TTO021 - TÂM SỬA XE HÀN TIỆN | B22: 17 | C22: An Châu | D22: CTH008 | E22: ODF 6FO Chợ Bình Hòa | F22: S2-VLXD Đức Nhung | G22: 105.34328 | H22: 10.46179 | I22: 105.3428 | J22: 10.462767 | N22: 1 | Q22: 1 | S22: Lắp hộp Splitter trên tuyến cáp hiện hữu | T22: Truyến BTS CTH008 - Bến tàu chợ Bình Hòa | U22: 1 | V22: OK
A23: TTO021 - TÂM SỬA XE HÀN TIỆN | B23: 18 | C23: An Châu | D23: CTH008 | E23: S2-VLXD Đức Nhung | F23: S2-Quốc Phong | G23: 105.3428 | H23: 10.462767 | I23: 105.34235 | J23: 10.46295 | Q23: 1 | S23: Lắp hộp Splitter trên tuyến cáp hiện hữu | T23: Truyến BTS CTH008 - Bến tàu chợ Bình Hòa | U23: 1 | V23: OK | W23: Sửa toạ độ S2-VLXD Đức Nhung
A24: TTO021 - TÂM SỬA XE HÀN TIỆN | B24: 19 | C24: An Châu | D24: CTH008 | E24: S2-Quốc Phong | F24: S2-Sau Lưng Ngô Sồi | G24: 105.3419 | H24: 10.4628 | I24: 105.34104 | J24: 10.462651 | Q24: 1 | S24: Lắp hộp Splitter trên tuyến cáp hiện hữu | T24: Truyến BTS CTH008 - Bến tàu chợ Bình Hòa | U24: 1 | V24: OK
A25: TTO008 - THCS LQI 2 | B25: 20 | C25: An Châu | D25: CTH008 | E25: S2-Sau Lưng Ngô Sồi | F25: S2-Cuối đường dưới | G25: 105.34104 | H25: 10.462651 | I25: 105.3402 | J25: 10.462345 | Q25: 1 | S25: Lắp hộp Splitter trên tuyến cáp hiện hữu | T25: Truyến BTS CTH008 - Bến tàu chợ Bình Hòa | U25: 1 | V25: OK
A26: TTO008 - THCS LQI 2 | B26: 21 | C26: An Châu | D26: CTH036 | E26: ODF 6FO bờ UB Bình Thạnh | F26: S2-Bờ UB Bình Thạnh 1 | G26: 105.34903 | H26: 10.467878 | I26: 105.34987 | J26: 10.46872 | N26: 1 | Q26: 1 | S26: Lắp hộp Splitter trên tuyến cáp hiện hữu | T26: Tuyến BTS CTH036 - Hướng UB xã Bình Thạnh cũ | U26: 1 | V26: OK | W26: Sửa toạ độ ODF 6FO bờ UB Bình Thạnh
A27: TTO008 - THCS LQI 2 | B27: 22 | C27: An Châu | D27: CTH036 | E27: S2-Bờ UB Bình Thạnh 1 | F27: S2-Bờ UB Bình Thạnh 2 | G27: 105.34987 | H27: 10.46872 | I27: 105.35073 | J27: 10.468719 | Q27: 1 | S27: Lắp hộp Splitter trên tuyến cáp hiện hữu | T27: Tuyến BTS CTH036 - Hướng UB xã Bình Thạnh cũ | U27: 1 | V27: OK | W27: Lắp tủ tuyến cáp có sẵn để sang thuê bao về bờ bên đây, giảm tải cho các tủ ở tuyến bên kia sông
A28: TTO008 - THCS LQI 2 | B28: 23 | C28: An Châu | D28: CTH036 | E28: S2-Bờ UB Bình Thạnh 2 | F28: S2-Bờ UB Bình Thạnh 3 | G28: 105.3522 | H28: 10.468254 | I28: 105.3522 | J28: 10.468254 | Q28: 1 | S28: Lắp hộp Splitter trên tuyến cáp hiện hữu | T28: Tuyến BTS CTH036 - Hướng UB xã Bình Thạnh cũ | U28: 1 | V28: OK | W28: Lắp tủ tuyến cáp có sẵn để sang thuê bao về bờ bên đây, giảm tải cho các tủ ở tuyến bên kia sông
A29: TTN.LQI.OLT.A21.1.7.3_Cầu Lạc Quới 2 - VĨNH LỘC 3 | B29: 24 | C29: An Châu | D29: CTH036 | E29: S2-Bờ UB Bình Thạnh 3 | F29: S2-Bờ UB Bình Thạnh 4 | G29: 105.35449 | H29: 10.466701 | I29: 105.35321 | J29: 10.467749 | Q29: 1 | S29: Lắp hộp Splitter trên tuyến cáp hiện hữu | T29: Tuyến BTS CTH036 - Hướng UB xã Bình Thạnh cũ | U29: 1 | V29: OK | W29: Lắp tủ tuyến cáp có sẵn để sang thuê bao về bờ bên đây, giảm tải cho các tủ ở tuyến bên kia sông
A30: TTN.LQI.OLT.A21.1.7.3_Cầu Lạc Quới 2 - VĨNH LỘC 3 | B30: 25 | C30: An Châu | D30: CTH036 | E30: S2-Bờ UB Bình Thạnh 4 | F30: S2-Bờ UB Bình Thạnh 5 | G30: 105.36515 | H30: 10.46584 | I30: 105.35449 | J30: 10.467014 | N30: 1 | Q30: 1 | S30: Lắp hộp Splitter trên tuyến cáp hiện hữu | T30: Tuyến BTS CTH036 - Hướng UB xã Bình Thạnh cũ | U30: 1 | V30: OK | W30: Lắp tủ tuyến cáp có sẵn để sang thuê bao về bờ bên đây, giảm tải cho các tủ ở tuyến bên kia sông
A31: TTN.LQI.OLT.A21.1.7.3_Cầu Lạc Quới 2 - VĨNH LỘC 3 | B31: 26 | C31: An Châu | D31: CTH036 | E31: S2-Bờ UB Bình Thạnh 5 | F31: S2-Bờ UB Bình Thạnh 6 | G31: 105.35804 | H31: 10.464707 | I31: 105.35615 | J31: 10.46584 | Q31: 1 | S31: Lắp hộp Splitter trên tuyến cáp hiện hữu | T31: Tuyến BTS CTH036 - Hướng UB xã Bình Thạnh cũ | U31: 1 | V31: OK | W31: Lắp tủ tuyến cáp có sẵn để sang thuê bao về bờ bên đây, giảm tải cho các tủ ở tuyến bên kia sông
A32: TTN.LQI.OLT.A21.1.7.3_Cầu Lạc Quới 2 - VĨNH LỘC 3 | B32: 27 | C32: An Châu | D32: CTH036 | E32: S2-Bờ UB Bình Thạnh 6 | F32: S2-Bờ UB Bình Thạnh 7 | G32: 105.35449 | H32: 10.467014 | I32: 105.35804 | J32: 10.464707 | Q32: 1 | S32: Lắp hộp Splitter trên tuyến cáp hiện hữu | T32: Tuyến BTS CTH036 - Hướng UB xã Bình Thạnh cũ | U32: 1 | V32: OK | W32: Lắp tủ tuyến cáp có sẵn để sang thuê bao về bờ bên đây, giảm tải cho các tủ ở tuyến bên kia sông
A33: TTN.LQI.OLT.A21.1.7.3_Cầu Lạc Quới 2 - VĨNH LỘC 3 | B33: 28 | C33: An Châu | D33: CTH036 | E33: S2-Bờ UB Bình Thạnh 7 | F33: S2-Bờ UB Bình Thạnh 8 | G33: 105.35615 | H33: 10.46584 | I33: 105.35986 | J33: 10.463579 | Q33: 1 | S33: Lắp hộp Splitter trên tuyến cáp hiện hữu | T33: Tuyến BTS CTH036 - Hướng UB xã Bình Thạnh cũ | U33: 1 | V33: OK | W33: Lắp tủ tuyến cáp có sẵn để sang thuê bao về bờ bên đây, giảm tải cho các tủ ở tuyến bên kia sông
A34: TTN.LQI.OLT.A21.1.7.3_Cầu Lạc Quới 2 - VĨNH LỘC 3 | B34: 29 | C34: An Châu | D34: CTH021 | E34: ODF 12F0 CTH021 Kinh Đứng | F34: S2-Trước trạm CTH021 | G34: 105.32417 | H34: 10.36174 | I34: 105.3238 | J34: 10.362037 | K34: 120 | N34: 1 | Q34: 1 | R34: 1 | T34: Tuyến BTS CTH021 - Kênh Đứng | U34: 1 | V34: OK
A35: TTN.LQI.OLT.A21.1.7.3_Cầu Lạc Quới 2 - VĨNH LỘC 3 | B35: 30 | C35: An Châu | D35: CTH021 | E35: S2-Trước trạm CTH021 | F35: S2-Quầy thuốc số 9 | G35: 105.3238 | H35: 10.362037 | I35: 105.32466 | J35: 10.363193 | K35: 300 | Q35: 1 | T35: Tuyến BTS CTH021 - Kênh Đứng | U35: 1 | V35: OK | W35: Sửa lại toạ độ S2-Quầy thuốc số 9
A36: TTN.LQI.OLT.A21.1.7.3_Cầu Lạc Quới 2 - VĨNH LỘC 3 | B36: 31 | C36: An Châu | D36: CTH021 | E36: S2-Quầy thuốc số 9 | F36: S2-Nhà nghỉ Tân Thành | G36: 105.32466 | H36: 10.363193 | I36: 105.32693 | J36: 10.365916 | K36: 300 | Q36: 1 | T36: Tuyến BTS CTH021 - Kênh Đứng | U36: 1 | V36: OK
A37: TTN.LQI.OLT.A21.1.7.3_Cầu Lạc Quới 2 - VĨNH LỘC 3 | B37: 32 | C37: An Châu | D37: CTH021 | E37: S2-Nhà nghỉ Tân Thành | F37: S2-Ngoài nhà nghỉ Tân Thành | G37: 105.32693 | H37: 10.365916 | I37: 105.32779 | J37: 10.366925 | K37: 280 | Q37: 1 | T37: Tuyến BTS CTH021 - Kênh Đứng | U37: 1 | V37: OK | W37: Sửa lại toạ độ S2-Ngoài nhà nghỉ Tân Thành
A38: TTN.LQI.OLT.A21.1.7.3_Cầu Lạc Quới 2 - VĨNH LỘC 3 | B38: 33 | C38: An Châu | D38: CTH021 | E38: S2-Ngoài nhà nghỉ Tân Thành | F38: S2-Cầu cống đá | G38: 105.32779 | H38: 10.366925 | I38: 105.33026 | J38: 10.36989 | K38: 370 | N38: 1 | Q38: 1 | T38: Tuyến BTS CTH021 - Kênh Đứng | U38: 1 | V38: OK
A39: TTN.LQI.OLT.A21.1.7.3_Cầu Lạc Quới 2 - VĨNH LỘC 3 | B39: 34 | C39: An Châu | D39: CTH021 | E39: S2-Cầu cống đá | F39: S2-Ngoài cầu cống đá | G39: 105.33026 | H39: 10.36989 | I39: 105.33093 | J39: 10.370727 | K39: 250 | Q39: 1 | T39: Tuyến BTS CTH021 - Kênh Đứng | U39: 1 | V39: OK | W39: Sửa toạ độ S2-Ngoài cầu cống đá
A40: TTN.LQI.OLT.A21.1.7.3_Cầu Lạc Quới 2 - VĨNH LỘC 3 | B40: 35 | C40: An Châu | D40: CTH021 | E40: S2-Ngoài cầu cống đá | F40: S2-Trong cầu Tân Thành 4 | G40: 105.33093 | H40: 10.370727 | I40: 105.33351 | J40: 10.373796 | K40: 200 | Q40: 1 | T40: Tuyến BTS CTH021 - Kênh Đứng | U40: 1 | V40: OK
A41: TTN.LQI.OLT.A21.1.7.3_Cầu Lạc Quới 2 - VĨNH LỘC 3 | B41: 36 | C41: An Châu | D41: CTH021 | E41: S2-Trong cầu Tân Thành 4 | F41: S2-Trong cầu 3 chùa | G41: 105.33351 | H41: 10.373796 | I41: 105.33533 | J41: 10.376045 | K41: 370 | Q41: 1 | T41: Tuyến BTS CTH021 - Kênh Đứng | U41: 1 | V41: OK
...

Sheet APU_OK
B1: VTAG - TỔNG HỢP NHU CẦU CÁP QUANG GPON 2026
B3: TỔNG CỘNG: | I3: TTVT AN PHÚ | K3: =SUMIF($C$6:$C$4265,"An Phú",K6:K4265) -> 17000 | L3: =SUMIF($C$6:$C$4265,"An Phú",L6:L4265) -> 0 | M3: =SUMIF($C$6:$C$4265,"An Phú",M6:M4265) -> 0 | N3: =SUMIF($C$6:$C$4265,"An Phú",N6:N4265) -> 23 | O3: =SUMIF($C$6:$C$4265,"An Phú",O6:O4265) -> 0 | P3: =SUMIF($C$6:$C$4265,"An Phú",P6:P4265) -> 0 | Q3: =SUMIF($C$6:$C$4265,"An Phú",Q6:Q4265) -> 86 | R3: =SUMIF($C$6:$C$4265,"An Phú",R6:R4265) -> 2
A4: TUYẾN TỔNG HỢP | B4: STT | C4: Đơn vị | D4: OLT | E4: ĐIỂM ĐẦU A | F4: ĐIỂM ĐẦU B | G4: Tọa độ A | I4: Tọa độ B | K4: Cáp quang 6FO(m) | L4: Cáp quang 12FO(m) | M4: Cáp quang 24FO(m) | N4: SP 1:4 | O4: SP 1: 8 (S1) | P4: SP 1: 8 (S2) | Q4: SP 1: 16 | R4: ODF | S4: Ghi chú | T4: Thông tin bên Biểu 3_MẠNg GPON | U4: Mức độ Ưu tiên từ 1-3 | V4: TTHT CHECK
G5: Long | H5: lat | I5: Long | J5: lat | K5: =SUBTOTAL(9,K6:K3841) -> 17000 | L5: =SUBTOTAL(9,L6:L3841) -> 0 | M5: =SUBTOTAL(9,M6:M3841) -> 0 | N5: =SUBTOTAL(9,N6:N3841) -> 23 | O5: =SUBTOTAL(9,O6:O3841) -> 0 | P5: =SUBTOTAL(9,P6:P3841) -> 0 | Q5: =SUBTOTAL(9,Q6:Q3841) -> 86 | R5: =SUBTOTAL(9,R6:R3841) -> 2 | V5: KẾT QUẢ | W5: LÍ DO
A6: Trạm CMO048 - Tuấn Bưu tá | B6: 1 | C6: An Phú | D6: APH004 | E6: Nhập trạm 004 | F6: Ấp Vĩnh Khánh | G6: 105.05751 | H6: 10.914693 | I6: 105.05746 | J6: 10.915060, | K6: 100 | R6: 1 | T6: Tuyến Búng Lớn - BBT | U6: 1 | V6: OK | W6: Bổ sung thêm tủ cho tuyến hiện tại
A7: Trạm CMO048 - Tuấn Bưu tá | B7: 2 | C7: An Phú | D7: APH004 | E7: Ấp Vĩnh Khánh | F7: Bàn bida | G7: 105.43069 | H7: 10.38002 | I7: 105.0582 | J7: 10.915259 | K7: 175 | Q7: 1 | T7: Tuyến Búng Lớn - BBT | U7: 1 | V7: OK | W7: Bổ sung thêm tủ cho tuyến hiện tại
A8: Trạm CMO048 - Tuấn Bưu tá | B8: 3 | C8: An Phú | D8: APH004 | E8: Bàn bida | F8: Nhà thầy tưởng | G8: 105.05821 | H8: 10.915285 | I8: 105.05821 | J8: 10.915285 | K8: 140 | Q8: 1 | T8: Tuyến Búng Lớn - BBT | U8: 1 | V8: OK | W8: Bổ sung thêm tủ cho tuyến hiện tại
A9: Cầu Kênh Xáng AB - Cầu Kênh Xáng AB 5 | B9: 4 | C9: An Phú | D9: APH004 | E9: Nhà thầy tưởng | F9: Nhà anh Thắng | G9: 105.05914 | H9: 10.915403 | I9: 105.05914 | J9: 10.915403 | K9: 200 | N9: 1 | Q9: 1 | T9: Tuyến Búng Lớn - BBT | U9: 1 | V9: OK | W9: Bổ sung thêm tủ cho tuyến hiện tại
A10: Cầu Kênh Xáng AB - Cầu Kênh Xáng AB 5 | B10: 5 | C10: An Phú | D10: APH004 | E10: Nhà anh Thắng | F10: Café Aysa | G10: 105.05977 | H10: 10.915165 | I10: 105.05977 | J10: 10.915165 | K10: 200 | Q10: 1 | T10: Tuyến Búng Lớn - BBT | U10: 1 | V10: OK | W10: Bổ sung thêm tủ cho tuyến hiện tại
A11: Cầu Kênh Xáng AB - Cầu Kênh Xáng AB 5 | B11: 6 | C11: An Phú | D11: APH004 | E11: Café Aysa | F11: VTNN CaLy | G11: 105.06123 | H11: 10.915522 | I11: 105.06123 | J11: 10.915522 | K11: 285 | Q11: 1 | T11: Tuyến Búng Lớn - BBT | U11: 1 | V11: OK | W11: Bổ sung thêm tủ cho tuyến hiện tại
A12: Cầu Kênh Xáng AB - Cầu Kênh Xáng AB 5 | B12: 7 | C12: An Phú | D12: APH004 | E12: VTNN CaLy | F12: Thánh Đường Lớn | G12: 105.06316 | H12: 10.915858 | I12: 105.06316 | J12: 10.915858 | K12: 180 | Q12: 1 | T12: Tuyến Búng Lớn - BBT | U12: 1 | V12: OK | W12: Bổ sung thêm tủ cho tuyến hiện tại
A13: Cầu Kênh Xáng AB - Cầu Kênh Xáng AB 5 | B13: 8 | C13: An Phú | D13: APH004 | E13: Thánh Đường Lớn | F13: Chùa Chăm BBT | G13: 105.06403 | H13: 10.915626 | I13: 105.06403 | J13: 10.915626 | K13: 220 | Q13: 1 | T13: Tuyến Búng Lớn - BBT | U13: 1 | V13: OK | W13: Bổ sung thêm tủ cho tuyến hiện tại
A14: TUYẾN MỚI ĐƠN VỊ NHU CẦU KHẨN CẤP THÊM | B14: 9 | C14: An Phú | D14: APH004 | E14: Chùa Chăm BBT | F14: Cổng Chào | G14: 105.06544 | H14: 10.915626 | I14: 105.06544 | J14: 10.915626 | K14: 120 | N14: 1 | Q14: 1 | T14: Tuyến Búng Lớn - BBT | U14: 1 | V14: OK | W14: Bổ sung thêm tủ cho tuyến hiện tại
A15: Cầu T7 - Kênh T7 | B15: 10 | C15: An Phú | D15: APH004 | E15: Cổng Chào | F15: Ấp 3 BBT | G15: 105.06544 | H15: 10.915626 | I15: 105.06544 | J15: 10.915626 | K15: 240 | Q15: 1 | T15: Tuyến Búng Lớn - BBT | U15: 1 | V15: OK | W15: Bổ sung thêm tủ cho tuyến hiện tại
A16: Dưới Bến Đò DT - PON Thị Đầy | B16: 11 | C16: An Phú | D16: APH004 | E16: Ấp 3 BBT | F16: Nhà anh Thơ | G16: 105.0695 | H16: 10.915386 | I16: 105.0695 | J16: 10.915386 | K16: 240 | Q16: 1 | T16: Tuyến Búng Lớn - BBT | U16: 1 | V16: OK | W16: Bổ sung thêm tủ cho tuyến hiện tại
A17: Dưới Bến Đò DT - PON Thị Đầy | B17: 12 | C17: An Phú | D17: APH004 | E17: Nhà anh Thơ | F17: Trạm APH034 | G17: 105.06544 | H17: 10.915626 | I17: 105.07094 | J17: 10.915921 | K17: 300 | Q17: 1 | T17: Tuyến Búng Lớn - BBT | U17: 1 | V17: OK | W17: Bổ sung thêm tủ cho tuyến hiện tại
A18: Dưới Bến Đò DT - PON Thị Đầy | B18: 13 | C18: An Phú | D18: APH004 | E18: Trạm APH034 | F18: Game Dũng | G18: 105.07094 | H18: 10.915921 | I18: 105.06544 | J18: 10.915626 | K18: 320 | Q18: 1 | T18: Tuyến Búng Lớn - BBT | U18: 1 | V18: OK | W18: Bổ sung thêm tủ cho tuyến hiện tại
A19: Dưới Bến Đò DT - PON Thị Đầy | B19: 14 | C19: An Phú | D19: APH004 | E19: Game Dũng | F19: Rửa xe Tài | G19: 105.06544 | H19: 10.915626 | I19: 105.0784 | J19: 10.919 | K19: 320 | N19: 1 | Q19: 1 | T19: Tuyến Búng Lớn - BBT | U19: 1 | V19: OK | W19: Bổ sung thêm tủ cho tuyến hiện tại
A20: Dưới Bến Đò DT - PON Thị Đầy | B20: 15 | C20: An Phú | D20: APH004 | E20: Rửa xe Tài | F20: Nhà Nghỉ Kiều Oanh | G20: 105.0784 | H20: 10.919 | I20: 105.083 | J20: 10.9208 | K20: 330 | Q20: 1 | T20: Tuyến Búng Lớn - BBT | U20: 1 | V20: OK | W20: Bổ sung thêm tủ cho tuyến hiện tại
A21: 007 - K7 Chủ Mỹ OLT - S2-007 - K7 Chủ Mỹ 8 CUỐI | B21: 16 | C21: An Phú | D21: APH014 | E21: Trường Mẫu Giáo | F21: Salon Mai Thảo | G21: 105.06722 | H21: 10.79412 | I21: 105.06687 | J21: 10.79368 | K21: 150 | Q21: 1 | T21: Bến đò Dung Thăng | U21: 1 | V21: OK | W21: Bổ sung thêm tủ cho tuyến hiện tại
A22: 007 - K7 Chủ Mỹ OLT - S2-007 - K7 Chủ Mỹ 8 CUỐI | B22: 17 | C22: An Phú | D22: APH014 | E22: Salon Mai Thảo | F22: KDC 1 | G22: 105.06687 | H22: 10.79368 | I22: 105.06712 | J22: 10.79415 | K22: 100 | N22: 1 | Q22: 1 | T22: Bến đò Dung Thăng | U22: 1 | V22: OK | W22: Bổ sung thêm tủ cho tuyến hiện tại
A23: Trạm Phú Vĩnh -Đường đất Phú Vĩnh 25 | B23: 18 | C23: An Phú | D23: APH014 | E23: KDC 1 | F23: KDC 2 | G23: 105.06712 | H23: 10.79415 | I23: 105.06761 | J23: 10.79525 | K23: 250 | Q23: 1 | T23: Bến đò Dung Thăng | U23: 1 | V23: OK | W23: Bổ sung thêm tủ cho tuyến hiện tại
A24: Trạm Phú Vĩnh -Đường đất Phú Vĩnh 25 | B24: 19 | C24: An Phú | D24: APH014 | E24: KDC 2 | F24: KDC 3 | G24: 105.06761 | H24: 10.79525 | I24: 105.06731 | J24: 10.79534 | K24: 150 | Q24: 1 | T24: Bến đò Dung Thăng | U24: 1 | V24: OK | W24: Bổ sung thêm tủ cho tuyến hiện tại
A25: Trạm Phú Vĩnh -Đường đất Phú Vĩnh 25 | B25: 20 | C25: An Phú | D25: APH014 | E25: Dưới Bến Đò DT | F25: Út Hiếu | G25: 105.06814 | H25: 10.78808 | I25: 105.06994 | J25: 10.78781 | K25: 200 | Q25: 1 | T25: Bến đò Dung Thăng | U25: 1 | V25: OK | W25: Bổ sung thêm tủ cho tuyến hiện tại
A26: Trạm Phú Vĩnh -Đường đất Phú Vĩnh 25 | B26: 21 | C26: An Phú | D26: APH014 | E26: Út Hiếu | F26: Nhà 875 | G26: 105.06994 | H26: 10.78781 | I26: 105.07094 | J26: 10.7879 | K26: 150 | N26: 1 | Q26: 1 | T26: Bến đò Dung Thăng | U26: 1 | V26: OK | W26: Bổ sung thêm tủ cho tuyến hiện tại
A27: Trạm Phú Vĩnh -Đường đất Phú Vĩnh 25 | B27: 22 | C27: An Phú | D27: APH014 | E27: Nhà 875 | F27: Nhà Yến | G27: 105.07094 | H27: 10.7879 | I27: 105.0731 | J27: 10.78837 | K27: 150 | Q27: 1 | T27: Bến đò Dung Thăng | U27: 1 | V27: OK | W27: Bổ sung thêm tủ cho tuyến hiện tại
A28: Trạm Phú Vĩnh -Đường đất Phú Vĩnh 25 | B28: 23 | C28: An Phú | D28: APH014 | E28: Nhà Yến | F28: Nhà Yến 2 | G28: 105.0731 | H28: 10.78837 | I28: 105.0734 | J28: 10.78858 | K28: 100 | Q28: 1 | T28: Bến đò Dung Thăng | U28: 1 | V28: OK | W28: Bổ sung thêm tủ cho tuyến hiện tại
A29: Trạm Phú Vĩnh -Đường đất Phú Vĩnh 25 | B29: 24 | C29: An Phú | D29: APH014 | E29: Nhà Yến 2 | F29: PON Văn Trọng | G29: 105.0734 | H29: 10.78858 | I29: 105.07513 | J29: 10.78913 | K29: 200 | Q29: 1 | T29: Bến đò Dung Thăng | U29: 1 | V29: OK | W29: Bổ sung thêm tủ cho tuyến hiện tại
A30: Trạm Phú Vĩnh -Đường đất Phú Vĩnh 25 | B30: 25 | C30: An Phú | D30: APH014 | E30: PON Văn Trọng | F30: Trên Ban Trị Sự | G30: 105.07513 | H30: 10.78913 | I30: 105.07666 | J30: 10.78957 | K30: 150 | N30: 1 | Q30: 1 | T30: Bến đò Dung Thăng | U30: 1 | V30: OK | W30: Bổ sung thêm tủ cho tuyến hiện tại
A31: Trạm Phú Vĩnh -Đường đất Phú Vĩnh 25 | B31: 26 | C31: An Phú | D31: APH014 | E31: Trên Ban Trị Sự | F31: Dưới Ban Trị Sự | G31: 105.07666 | H31: 10.78957 | I31: 105.07775 | J31: 10.78969 | K31: 150 | Q31: 1 | T31: Bến đò Dung Thăng | U31: 1 | V31: OK | W31: Bổ sung thêm tủ cho tuyến hiện tại
A32: Trạm Phú Vĩnh -Đường đất Phú Vĩnh 25 | B32: 27 | C32: An Phú | D32: APH014 | E32: Dưới Ban Trị Sự | F32: PON Văn Kháng | G32: 105.07775 | H32: 10.78969 | I32: 105.0805 | J32: 10.79064 | K32: 250 | Q32: 1 | T32: Bến đò Dung Thăng | U32: 1 | V32: OK | W32: Bổ sung thêm tủ cho tuyến hiện tại
A33: Trạm Phú Vĩnh -Đường đất Phú Vĩnh 25 | B33: 28 | C33: An Phú | D33: APH014 | E33: PON Văn Kháng | F33: PON Thị Đầy | G33: 105.0805 | H33: 10.79064 | I33: 105.08136 | J33: 10.79082 | K33: 150 | N33: 1 | Q33: 1 | T33: Bến đò Dung Thăng | U33: 1 | V33: OK | W33: Bổ sung thêm tủ cho tuyến hiện tại
A34: Trạm Phú Vĩnh -Đường đất Phú Vĩnh 25 | B34: 29 | C34: An Phú | D34: APH067 | E34: Đầu KDC kan | F34: Phế liệu | G34: 105.10915324 | H34: 10.95061633 | I34: 105.10851073 | J34: 10.95341289 | K34: 370 | N34: 1 | Q34: 1 | T34: KDC | U34: 1 | V34: OK | W34: Bổ sung thêm tủ cho tuyến hiện tại
A35: Trạm Phú Vĩnh -Đường đất Phú Vĩnh 25 | B35: 30 | C35: An Phú | D35: APH067 | E35: Phế liệu | F35: Vựa xoài Tuyền Tiến | G35: 105.10851073 | H35: 10.95341289 | I35: 105.10836813 | J35: 10.95369508 | K35: 60 | Q35: 1 | T35: KDC | U35: 1 | V35: OK | W35: Bổ sung thêm tủ cho tuyến hiện tại
A36: Trạm Phú Vĩnh -Đường đất Phú Vĩnh 25 | B36: 31 | C36: An Phú | D36: APH067 | E36: Vựa xoài Tuyền Tiến | F36: THCS Kan | G36: 105.10836813 | H36: 10.95369508 | I36: 105.10773281 | J36: 10.95503948 | K36: 200 | Q36: 1 | T36: KDC | U36: 1 | V36: OK | W36: Bổ sung thêm tủ cho tuyến hiện tại
A37: Trạm Phú Vĩnh -Đường đất Phú Vĩnh 25 | B37: 32 | C37: An Phú | D37: APH067 | E37: THCS Kan | F37: VP ấp An Khánh | G37: 105.10773281 | H37: 10.95503948 | I37: 105.10685349 | J37: 10.95620231 | K37: 200 | Q37: 1 | T37: KDC | U37: 1 | V37: OK | W37: Bổ sung thêm tủ cho tuyến hiện tại
A38: Trạm Phú Vĩnh -Đường đất Phú Vĩnh 25 | B38: 33 | C38: An Phú | D38: APH010 | E38: Tủ Hoàng Lĩnh | F38: Tủ Hai Hái | G38: 105.12721 | H38: 10.899763 | I38: 105.12691 | J38: 10.897951 | K38: 250 | Q38: 1 | T38: Tuyến dân cư Phú Lợi | U38: 1 | V38: OK | W38: Bổ sung thêm tủ cho tuyến hiện tại
A39: Trạm Phú Vĩnh -Đường đất Phú Vĩnh 25 | B39: 34 | C39: An Phú | D39: APH010 | E39: Tủ Hai Hái | F39: Tủ Chú Trẩm | G39: 105.12691 | H39: 10.897951 | I39: 105.12677 | J39: 10.896845 | K39: 200 | N39: 1 | Q39: 1 | T39: Tuyến dân cư Phú Lợi | U39: 1 | V39: OK | W39: Bổ sung thêm tủ cho tuyến hiện tại
A40: Trạm Phú Vĩnh -Đường đất Phú Vĩnh 25 | B40: 35 | C40: An Phú | D40: APH010 | E40: Tủ Chú Trẩm | F40: Tủ Thầy Bền | G40: 105.12677 | H40: 10.896845 | I40: 105.1267 | J40: 10.895562 | K40: 150 | Q40: 1 | T40: Tuyến dân cư Phú Lợi | U40: 1 | V40: OK | W40: Bổ sung thêm tủ cho tuyến hiện tại
A41: Trạm Phú Vĩnh -Đường đất Phú Vĩnh 25 | B41: 36 | C41: An Phú | D41: APH010 | E41: Tủ Thầy Bền | F41: Tủ Thuốc BVTV Tường Vy | G41: 105.1267 | H41: 10.895562 | I41: 105.1266 | J41: 10.895024 | K41: 150 | Q41: 1 | T41: Tuyến dân cư Phú Lợi | U41: 1 | V41: OK | W41: Bổ sung thêm tủ cho tuyến hiện tại
...

Sheet CĐC_OK
B1: VTAG - TỔNG HỢP NHU CẦU CÁP QUANG GPON 2026
B3: TỔNG CỘNG: | I3: TTVT CHÂU ĐỐC | K3: =SUMIF($C$6:$C$4281,"Châu Đốc",K6:K4280) -> 12000 | L3: =SUMIF($C$6:$C$4281,"Châu Đốc",L6:L4280) -> 0 | M3: =SUMIF($C$6:$C$4281,"Châu Đốc",M6:M4280) -> 0 | N3: =SUMIF($C$6:$C$4281,"Châu Đốc",N6:N4280) -> 16 | O3: =SUMIF($C$6:$C$4281,"Châu Đốc",O6:O4280) -> 0 | P3: =SUMIF($C$6:$C$4281,"Châu Đốc",P6:P4280) -> 0 | Q3: =SUMIF($C$6:$C$4281,"Châu Đốc",Q6:Q4280) -> 60 | R3: =SUMIF($C$6:$C$4281,"Châu Đốc",R6:R4280) -> 4
A4: TUYẾN TỔNG HỢP | B4: STT | C4: Đơn vị | D4: OLT | E4: ĐIỂM ĐẦU A | F4: ĐIỂM ĐẦU B | G4: Tọa độ A | I4: Tọa độ B | K4: Cáp quang 6FO(m) | L4: Cáp quang 12FO(m) | M4: Cáp quang 24FO(m) | N4: SP 1:4 | O4: SP 1: 8 (S1) | P4: SP 1: 8 (S2) | Q4: SP 1: 16 | R4: ODF | S4: Ghi chú | T4: Thông tin bên Biểu 3_MẠNg GPON | U4: Mức độ Ưu tiên từ 1-3 | V4: TTHT CHECK
G5: Long | H5: lat | I5: Long | J5: lat | K5: =SUBTOTAL(9,K6:K3933) -> 12000 | L5: =SUBTOTAL(9,L6:L3933) -> 0 | M5: =SUBTOTAL(9,M6:M3933) -> 0 | N5: =SUBTOTAL(9,N6:N3933) -> 16 | O5: =SUBTOTAL(9,O6:O3933) -> 0 | P5: =SUBTOTAL(9,P6:P3933) -> 0 | Q5: =SUBTOTAL(9,Q6:Q3933) -> 60 | R5: =SUBTOTAL(9,R6:R3933) -> 4 | V5: KẾT QUẢ | W5: LÍ DO
A6: KDC nvc - KDC NVC 2 | B6: 1 | C6: Châu Đốc | D6: Trạm Mỹ An | E6: trạm Mỹ An | F6: cách trạm Mỹ An 100m | G6: 105.13025 | H6: 10.681279 | I6: 105.13059 | J6: 10.6808 | K6: 150 | Q6: 1 | R6: 1 | T6: Tuyến Kênh 1 Mỹ Hòa | U6: 1 | V6: OK | W6: Thêm tủ vào giữa hạ tầng hiện hữu
A7: UBND XA CÔ TÔ - NGUYỄN THỊ SÁNG | B7: 2 | C7: Châu Đốc | D7: Trạm Mỹ An | E7: cách trạm Mỹ An 100m | F7: Xéo quán nhậu thảo lê | G7: 105.13059 | H7: 10.6808 | I7: 105.13172 | J7: 10.679643 | K7: 200 | N7: 1 | Q7: 1 | T7: Tuyến Kênh 1 Mỹ Hòa | U7: 1 | V7: OK | W7: Thêm tủ vào giữa hạ tầng hiện hữu
A8: UBND XA CÔ TÔ - NGUYỄN THỊ SÁNG | B8: 3 | C8: Châu Đốc | D8: Trạm Mỹ An | E8: Xéo quán nhậu thảo lê | F8: ngã 3 ra trạm 036 | G8: 105.13172 | H8: 10.679643 | I8: 105.13287 | J8: 10.678466 | K8: 200 | Q8: 1 | T8: Tuyến Kênh 1 Mỹ Hòa | U8: 1 | V8: OK | W8: Thêm tủ vào giữa hạ tầng hiện hữu
A9: UBND XA CÔ TÔ - NGUYỄN THỊ SÁNG | B9: 4 | C9: Châu Đốc | D9: Trạm Mỹ An | E9: ngã 3 ra trạm 036 | F9: xéo sửa xe Hoàng Phú | G9: 105.13287 | H9: 10.678466 | I9: 105.1337 | J9: 10.677602 | K9: 150 | Q9: 1 | T9: Tuyến Kênh 1 Mỹ Hòa | U9: 1 | V9: OK | W9: Thêm tủ vào giữa hạ tầng hiện hữu
A10: UBND XA CÔ TÔ - NGUYỄN THỊ SÁNG | B10: 5 | C10: Châu Đốc | D10: Trạm Mỹ An | E10: xéo sửa xe Hoàng Phú | F10: Vườn sen nốc nhà xanh | G10: 105.1337 | H10: 10.677602 | I10: 105.13513 | J10: 10.676124 | K10: 250 | Q10: 1 | T10: Tuyến Kênh 1 Mỹ Hòa | U10: 1 | V10: OK | W10: Thêm tủ vào giữa hạ tầng hiện hữu
A11: UBND XA CÔ TÔ - NGUYỄN THỊ SÁNG | B11: 6 | C11: Châu Đốc | D11: Trạm Mỹ An | E11: Vườn sen nốc nhà xanh | F11: Hầm cá mỹ an | G11: 105.13513 | H11: 10.676124 | I11: 105.13631 | J11: 10.674994 | K11: 200 | N11: 1 | Q11: 1 | T11: Tuyến Kênh 1 Mỹ Hòa | U11: 1 | V11: OK | W11: Thêm tủ vào giữa hạ tầng hiện hữu
A12: UBND XA CÔ TÔ - NGUYỄN THỊ SÁNG | B12: 7 | C12: Châu Đốc | D12: Trạm Mỹ An | E12: Hầm cá mỹ an | F12: gần cua mỹ an - mỹ hòa | G12: 105.13631 | H12: 10.674994 | I12: 105.13795 | J12: 10.673202 | K12: 200 | Q12: 1 | T12: Tuyến Kênh 1 Mỹ Hòa | U12: 1 | V12: OK | W12: Thêm tủ vào giữa hạ tầng hiện hữu
A13: UBND XA CÔ TÔ - NGUYỄN THỊ SÁNG | B13: 8 | C13: Châu Đốc | D13: Trạm Mỹ An | E13: gần cua mỹ an - mỹ hòa | F13: VTNN Tư Hồng | G13: 105.13795 | H13: 10.673202 | I13: 105.13751 | J13: 10.671537 | K13: 300 | Q13: 1 | T13: Tuyến Kênh 1 Mỹ Hòa | U13: 1 | V13: OK | W13: Thêm tủ vào giữa hạ tầng hiện hữu
A14: UBND XA CÔ TÔ - NGUYỄN THỊ SÁNG | B14: 9 | C14: Châu Đốc | D14: Trạm Mỹ An | E14: VTNN Tư Hồng | F14: băng sông kênh 2 | G14: 105.13751 | H14: 10.671537 | I14: 105.13756 | J14: 10.67084 | K14: 200 | Q14: 1 | T14: Tuyến trạm Bơm Kênh 2 Mỹ Đức | U14: 1 | V14: OK | W14: Thêm tủ vào giữa hạ tầng hiện hữu
A15: UBND XA CÔ TÔ - NGUYỄN THỊ SÁNG | B15: 10 | C15: Châu Đốc | D15: Trạm Mỹ An | E15: băng sông kênh 2 | F15: ĐD KDC Mỹ An bờ mỹ đức | G15: 105.13756 | H15: 10.67084 | I15: 105.13871 | J15: 10.672108 | K15: 200 | N15: 1 | Q15: 1 | T15: Tuyến trạm Bơm Kênh 2 Mỹ Đức | U15: 1 | V15: OK | W15: Thêm tủ vào giữa hạ tầng hiện hữu
A16: TTO021 - TÂM SỬA XE HÀN TIỆN | B16: 11 | C16: Châu Đốc | D16: Trạm Mỹ An | E16: băng sông kênh 2 | F16: băng sông quẹo phải 400m | G16: 105.13756 | H16: 10.67084 | I16: 105.13505 | J16: 10.668359 | K16: 400 | Q16: 1 | T16: Tuyến trạm Bơm Kênh 2 Mỹ Đức | U16: 1 | V16: OK | W16: Thêm tủ vào giữa hạ tầng hiện hữu
A17: TTO021 - TÂM SỬA XE HÀN TIỆN | B17: 12 | C17: Châu Đốc | D17: Trạm Mỹ An | E17: băng sông quẹo phải 400m | F17: hồ bao da phước | G17: 105.13505 | H17: 10.668359 | I17: 105.13398 | J17: 10.66728 | K17: 200 | Q17: 1 | T17: Tuyến trạm Bơm Kênh 2 Mỹ Đức | U17: 1 | V17: OK | W17: Thêm tủ vào giữa hạ tầng hiện hữu
A18: TTO021 - TÂM SỬA XE HÀN TIỆN | B18: 13 | C18: Châu Đốc | D18: Trạm Mỹ An | E18: hồ bao da phước | F18: xéo câu lạc bộ Friendly | G18: 105.13398 | H18: 10.66728 | I18: 105.13311 | J18: 10.666398 | K18: 150 | Q18: 1 | T18: Tuyến trạm Bơm Kênh 2 Mỹ Đức | U18: 1 | V18: OK | W18: Thêm tủ vào giữa hạ tầng hiện hữu
A19: TTO021 - TÂM SỬA XE HÀN TIỆN | B19: 14 | C19: Châu Đốc | D19: Trạm Mỹ An | E19: xéo câu lạc bộ Friendly | F19: xéo trạm 008 hướng kênh đào | G19: 105.13311 | H19: 10.666398 | I19: 105.13079 | J19: 10.663987 | K19: 400 | N19: 1 | Q19: 1 | T19: Tuyến trạm Bơm Kênh 2 Mỹ Đức | U19: 1 | V19: OK | W19: Thêm tủ vào giữa hạ tầng hiện hữu
A20: TTO021 - TÂM SỬA XE HÀN TIỆN | B20: 15 | C20: Châu Đốc | D20: Trạm Mỹ An | E20: xéo trạm 008 hướng kênh đào | F20: xéo trạm 008 hướng kênh 4 | G20: 105.13079 | H20: 10.663987 | I20: 105.12968 | J20: 10.66291 | K20: 200 | Q20: 1 | T20: Tuyến trạm Bơm Kênh 2 Mỹ Đức | U20: 1 | V20: OK | W20: Thêm tủ vào giữa hạ tầng hiện hữu
A21: TTO021 - TÂM SỬA XE HÀN TIỆN | B21: 16 | C21: Châu Đốc | D21: Trạm Mỹ An | E21: xéo trạm 008 hướng kênh 4 | F21: tr Tiểu Học D Mỹ Đức | G21: 105.12968 | H21: 10.66291 | I21: 105.12847 | J21: 10.661688 | K21: 200 | Q21: 1 | T21: Tuyến trạm Bơm Kênh 2 Mỹ Đức | U21: 1 | V21: OK | W21: Thêm tủ vào giữa hạ tầng hiện hữu
A22: TTO021 - TÂM SỬA XE HÀN TIỆN | B22: 17 | C22: Châu Đốc | D22: Trạm Mỹ An | E22: tr Tiểu Học D Mỹ Đức | F22: VTNN Hòa Hưng | G22: 105.12847 | H22: 10.661688 | I22: 105.12729 | J22: 10.660558 | K22: 200 | Q22: 1 | T22: Tuyến trạm Bơm Kênh 2 Mỹ Đức | U22: 1 | V22: OK | W22: Thêm tủ vào giữa hạ tầng hiện hữu
A23: TTO021 - TÂM SỬA XE HÀN TIỆN | B23: 18 | C23: Châu Đốc | D23: Trạm Mỹ An | E23: VTNN Hòa Hưng | F23: VTNN Hòa Hưng vào 200m | G23: 105.12729 | H23: 10.660558 | I23: 105.12624 | J23: 10.659429 | K23: 200 | N23: 1 | Q23: 1 | T23: Tuyến trạm Bơm Kênh 2 Mỹ Đức | U23: 1 | V23: OK | W23: Thêm tủ vào giữa hạ tầng hiện hữu
A24: TTO021 - TÂM SỬA XE HÀN TIỆN | B24: 19 | C24: Châu Đốc | D24: Trạm Mỹ An | E24: VTNN Hòa Hưng vào 200m | F24: Xéo ngã 3 kênh đê bao | G24: 105.12624 | H24: 10.659429 | I24: 105.12506 | J24: 10.658243 | K24: 200 | Q24: 1 | T24: Tuyến trạm Bơm Kênh 2 Mỹ Đức | U24: 1 | V24: OK | W24: Thêm tủ vào giữa hạ tầng hiện hữu
A25: TTO008 - THCS LQI 2 | B25: 20 | C25: Châu Đốc | D25: Trạm Mỹ An | E25: Xéo ngã 3 kênh đê bao | F25: Đd tạp hóa tuyết loan | G25: 105.12506 | H25: 10.658243 | I25: 105.12389 | J25: 10.657055 | K25: 200 | Q25: 1 | T25: Tuyến trạm Bơm Kênh 2 Mỹ Đức | U25: 1 | V25: OK | W25: Thêm tủ vào giữa hạ tầng hiện hữu
A26: TTO008 - THCS LQI 2 | B26: 21 | C26: Châu Đốc | D26: Trạm Mỹ An | E26: Đd tạp hóa tuyết loan | F26: Cách tạp hóa Tuyết em 50m hướng k5 | G26: 105.12389 | H26: 10.657055 | I26: 105.12237 | J26: 10.655507 | K26: 250 | Q26: 1 | T26: Tuyến trạm Bơm Kênh 2 Mỹ Đức | U26: 1 | V26: OK | W26: Thêm tủ vào giữa hạ tầng hiện hữu
A27: TTO008 - THCS LQI 2 | B27: 22 | C27: Châu Đốc | D27: Trạm Vĩnh Châu | E27: Anh Nguyễn | F27: Anh Nguyễn ra 150m | G27: 105.11583 | H27: 10.64896 | I27: 105.11672 | J27: 10.649827 | K27: 200 | N27: 1 | Q27: 1 | T27: bổ sung thêm | U27: 1 | V27: OK | W27: Tuyến mới
A28: TTO008 - THCS LQI 2 | B28: 23 | C28: Châu Đốc | D28: Trạm Vĩnh Châu | E28: Anh Nguyễn ra 150m | F28: ĐD CX Đoàn Minh Tộc | G28: 105.11672 | H28: 10.649827 | I28: 105.11755 | J28: 10.650684 | K28: 200 | Q28: 1 | T28: bổ sung thêm | U28: 1 | V28: OK | W28: Tuyến mới
A29: TTN.LQI.OLT.A21.1.7.3_Cầu Lạc Quới 2 - VĨNH LỘC 3 | B29: 24 | C29: Châu Đốc | D29: Trạm Vĩnh Châu | E29: ĐD CX Đoàn Minh Tộc | F29: ĐD CX Đoàn Minh Tộc ra 200m | G29: 105.11755 | H29: 10.650684 | I29: 105.11921 | J29: 10.652312 | K29: 300 | Q29: 1 | T29: bổ sung thêm | U29: 1 | V29: OK | W29: Tuyến mới
A30: TTN.LQI.OLT.A21.1.7.3_Cầu Lạc Quới 2 - VĨNH LỘC 3 | B30: 25 | C30: Châu Đốc | D30: Trạm Vĩnh Châu | E30: Biệt thự k5 | F30: Trạm xăng k5 | G30: 105.10596 | H30: 10.6397 | I30: 105.10673 | J30: 10.640448 | K30: 200 | Q30: 1 | T30: bổ sung thêm | U30: 1 | V30: OK | W30: Tuyến mới
A31: TTN.LQI.OLT.A21.1.7.3_Cầu Lạc Quới 2 - VĨNH LỘC 3 | B31: 26 | C31: Châu Đốc | D31: Trạm Vĩnh Châu | E31: Trạm xăng k5 | F31: Ngã 3 kênh Xuất Khẩu Mỹ Thuận | G31: 105.10673 | H31: 10.640448 | I31: 105.1075 | J31: 10.641296 | K31: 200 | N31: 1 | Q31: 1 | T31: bổ sung thêm | U31: 1 | V31: OK | W31: Tuyến mới
A32: TTN.LQI.OLT.A21.1.7.3_Cầu Lạc Quới 2 - VĨNH LỘC 3 | B32: 27 | C32: Châu Đốc | D32: Trạm Vĩnh Châu | E32: Biệt thự k5 | F32: Cầu dây k5 | G32: 105.10596 | H32: 10.6397 | I32: 105.10504 | J32: 10.638841 | K32: 250 | Q32: 1 | T32: bổ sung thêm | U32: 1 | V32: OK | W32: Tuyến mới
A33: TTN.LQI.OLT.A21.1.7.3_Cầu Lạc Quới 2 - VĨNH LỘC 3 | B33: 28 | C33: Châu Đốc | D33: Trạm Vĩnh Châu | E33: Cầu dây k5 | F33: Cầu dây k5 vào 200m | G33: 105.10504 | H33: 10.638841 | I33: 105.10393 | J33: 10.637585 | K33: 250 | Q33: 1 | T33: bổ sung thêm | U33: 1 | V33: OK | W33: Tuyến mới
A34: TTN.LQI.OLT.A21.1.7.3_Cầu Lạc Quới 2 - VĨNH LỘC 3 | B34: 29 | C34: Châu Đốc | D34: Trạm Vĩnh Châu | E34: Cầu dây k5 vào 200m | F34: Trạm AGCD20 | G34: 105.10393 | H34: 10.637585 | I34: 105.10236 | J34: 10.636018 | K34: 200 | Q34: 1 | T34: bổ sung thêm | U34: 1 | V34: OK | W34: Tuyến mới
A35: TTN.LQI.OLT.A21.1.7.3_Cầu Lạc Quới 2 - VĨNH LỘC 3 | B35: 30 | C35: Châu Đốc | D35: Trạm Vĩnh Châu | E35: Trạm AGCD20 | F35: Trạm AGCD20 vào 200m | G35: 105.10236 | H35: 10.636018 | I35: 105.1005 | J35: 10.634134 | K35: 250 | N35: 1 | Q35: 1 | T35: bổ sung thêm | U35: 1 | V35: OK | W35: Tuyến mới
A36: TTN.LQI.OLT.A21.1.7.3_Cầu Lạc Quới 2 - VĨNH LỘC 3 | B36: 31 | C36: Châu Đốc | D36: Trạm Vĩnh Châu | E36: Trạm AGCD20 vào 200m | F36: xéo KDC chợ LONG BÌNH | G36: 105.1005 | H36: 10.634134 | I36: 105.09967 | J36: 10.633342 | K36: 200 | Q36: 1 | T36: bổ sung thêm | U36: 1 | V36: OK | W36: Tuyến mới
A37: TTN.LQI.OLT.A21.1.7.3_Cầu Lạc Quới 2 - VĨNH LỘC 3 | B37: 32 | C37: Châu Đốc | D37: Trạm Châu Đốc | E37: Tủ 300 NVT | F37: Cửa hàng đồ chơi gia Dũ | G37: 105.11474 | H37: 10.706751 | I37: 105.11536 | J37: 10.707157 | K37: 100 | N37: 1 | Q37: 1 | T37: bổ sung thêm | U37: 1 | V37: OK | W37: Nâng dung lượng cho tuyến hiện hữu
A38: TTN.LQI.OLT.A21.1.7.3_Cầu Lạc Quới 2 - VĨNH LỘC 3 | B38: 33 | C38: Châu Đốc | D38: Trạm Châu Đốc | E38: Cửa hàng đồ chơi gia Dũ | F38: Xôi gà Cô Hồng | G38: 105.11536 | H38: 10.707157 | I38: 105.11606 | J38: 10.707665 | K38: 100 | Q38: 1 | T38: bổ sung thêm | U38: 1 | V38: OK | W38: Nâng dung lượng cho tuyến hiện hữu
A39: TTN.LQI.OLT.A21.1.7.3_Cầu Lạc Quới 2 - VĨNH LỘC 3 | B39: 34 | C39: Châu Đốc | D39: Trạm Châu Đốc | E39: Xôi gà Cô Hồng | F39: LUCY SPA Châu Đốc | G39: 105.11606 | H39: 10.707665 | I39: 105.11653 | J39: 10.708011 | K39: 150 | Q39: 1 | T39: bổ sung thêm | U39: 1 | V39: OK | W39: Nâng dung lượng cho tuyến hiện hữu
A40: TTN.LQI.OLT.A21.1.7.3_Cầu Lạc Quới 2 - VĨNH LỘC 3 | B40: 35 | C40: Châu Đốc | D40: Trạm Châu Đốc | E40: LUCY SPA Châu Đốc | F40: Khá Thuận | G40: 105.11653 | H40: 10.708011 | I40: 105.11702 | J40: 10.708362 | K40: 100 | N40: 1 | Q40: 1 | T40: bổ sung thêm | U40: 1 | V40: OK | W40: Nâng dung lượng cho tuyến hiện hữu
A41: TTN.LQI.OLT.A21.1.7.3_Cầu Lạc Quới 2 - VĨNH LỘC 3 | B41: 36 | C41: Châu Đốc | D41: Trạm Châu Đốc | E41: Tủ 300 NVT | F41: Nhà thước Khôi Nguyên | G41: 105.11474 | H41: 10.706751 | I41: 105.11419 | J41: 10.706409 | K41: 100 | Q41: 1 | T41: bổ sung thêm | U41: 1 | V41: OK | W41: Nâng dung lượng cho tuyến hiện hữu
...

Sheet CPU_OK
B1: VTAG - TỔNG HỢP NHU CẦU CÁP QUANG GPON 2026
B3: TỔNG CỘNG: | I3: TTVT CHÂU PHÚ | K3: =SUMIF($C$6:$C$4310,"Châu Phú",K6:K4309) -> 18000 | L3: =SUMIF($C$6:$C$4310,"Châu Phú",L6:L4309) -> 0 | M3: =SUMIF($C$6:$C$4310,"Châu Phú",M6:M4309) -> 0 | N3: =SUMIF($C$6:$C$4310,"Châu Phú",N6:N4309) -> 21 | O3: =SUMIF($C$6:$C$4310,"Châu Phú",O6:O4309) -> 0 | P3: =SUMIF($C$6:$C$4310,"Châu Phú",P6:P4309) -> 0 | Q3: =SUMIF($C$6:$C$4310,"Châu Phú",Q6:Q4309) -> 84 | R3: =SUMIF($C$6:$C$4310,"Châu Phú",R6:R4309) -> 5
A4: TUYẾN TỔNG HỢP | B4: STT | C4: Đơn vị | D4: OLT | E4: ĐIỂM ĐẦU A | F4: ĐIỂM ĐẦU B | G4: Tọa độ A | I4: Tọa độ B | K4: Cáp quang 6FO(m) | L4: Cáp quang 12FO(m) | M4: Cáp quang 24FO(m) | N4: SP 1:4 | O4: SP 1: 8 (S1) | P4: SP 1: 8 (S2) | Q4: SP 1: 16 | R4: ODF | S4: Ghi chú | T4: Thông tin bên Biểu 3_MẠNg GPON | U4: Mức độ Ưu tiên từ 1-3 | V4: TTHT CHECK
G5: Long | H5: lat | I5: Long | J5: lat | K5: =SUBTOTAL(9,K6:K3998) -> 18000 | L5: =SUBTOTAL(9,L6:L3998) -> 0 | M5: =SUBTOTAL(9,M6:M3998) -> 0 | N5: =SUBTOTAL(9,N6:N3998) -> 21 | O5: =SUBTOTAL(9,O6:O3998) -> 0 | P5: =SUBTOTAL(9,P6:P3998) -> 0 | Q5: =SUBTOTAL(9,Q6:Q3998) -> 84 | R5: =SUBTOTAL(9,R6:R3998) -> 5 | V5: KẾT QUẢ | W5: LÍ DO
A6: TUYẾN MỚI ĐƠN VỊ NHU CẦU KHẨN CẤP THÊM | B6: 1 | C6: Châu Phú | D6: CPH023 | E6: Trạm CPH023 | F6: S2-TMT- Kênh 9-1 | G6: 105.14714 | H6: 10.54137 | I6: 105.14659 | J6: 10.54209 | K6: 160 | Q6: 1 | R6: 1 | T6: Tuyến BTS CPH023 - Kênh 9 | U6: 1 | V6: OK | W6: Bổ sung hạ tầng đan xen tuyến hiện tại
A7: Cầu T7 - Kênh T7 | B7: 2 | C7: Châu Phú | D7: CPH023 | E7: S2-TMT- Kênh 9-1 | F7: S2-TMT- Kênh 9-2 | G7: 105.14659 | H7: 10.54209 | I7: 105.14618 | J7: 10.54343 | K7: 210 | N7: 1 | Q7: 1 | T7: Tuyến BTS CPH023 - Kênh 9 | U7: 1 | V7: OK | W7: Bổ sung hạ tầng đan xen tuyến hiện tại
A8: Dưới Bến Đò DT - PON Thị Đầy | B8: 3 | C8: Châu Phú | D8: CPH023 | E8: S2-TMT- Kênh 9-2 | F8: S2-TMT- Kênh 9-3 | G8: 105.14618 | H8: 10.54343 | I8: 105.1474 | J8: 10.54482 | K8: 210 | Q8: 1 | T8: Tuyến BTS CPH023 - Kênh 9 | U8: 1 | V8: OK | W8: Bổ sung hạ tầng đan xen tuyến hiện tại
A9: Dưới Bến Đò DT - PON Thị Đầy | B9: 4 | C9: Châu Phú | D9: CPH023 | E9: S2-TMT- Kênh 9-3 | F9: S2-TMT- Kênh 9-4 | G9: 105.1474 | H9: 10.54482 | I9: 105.14863 | J9: 10.54627 | K9: 210 | Q9: 1 | T9: Tuyến BTS CPH023 - Kênh 9 | U9: 1 | V9: OK | W9: Bổ sung hạ tầng đan xen tuyến hiện tại
A10: Dưới Bến Đò DT - PON Thị Đầy | B10: 5 | C10: Châu Phú | D10: CPH023 | E10: S2-TMT- Kênh 9-4 | F10: S2-TMT- Kênh 9-5 | G10: 105.14863 | H10: 10.54627 | I10: 105.14921 | J10: 10.54693 | K10: 130 | Q10: 1 | T10: Tuyến BTS CPH023 - Kênh 9 | U10: 1 | V10: OK | W10: Bổ sung hạ tầng đan xen tuyến hiện tại
A11: Dưới Bến Đò DT - PON Thị Đầy | B11: 6 | C11: Châu Phú | D11: CPH023 | E11: S2-TMT- Kênh 9-5 | F11: S2-TMT- Kênh 9-6 | G11: 105.14921 | H11: 10.54693 | I11: 105.15115 | J11: 10.5492 | K11: 270 | N11: 1 | Q11: 1 | T11: Tuyến BTS CPH023 - Kênh 9 | U11: 1 | V11: OK | W11: Bổ sung hạ tầng đan xen tuyến hiện tại
A12: Dưới Bến Đò DT - PON Thị Đầy | B12: 7 | C12: Châu Phú | D12: CPH023 | E12: S2-TMT- Kênh 9-6 | F12: S2-TMT- Kênh 9-7 | G12: 105.15115 | H12: 10.5492 | I12: 105.15303 | J12: 10.55134 | K12: 270 | Q12: 1 | T12: Tuyến BTS CPH023 - Kênh 9 | U12: 1 | V12: OK | W12: Bổ sung hạ tầng đan xen tuyến hiện tại
A13: Dưới Bến Đò DT - PON Thị Đầy | B13: 8 | C13: Châu Phú | D13: CPH023 | E13: S2-TMT- Kênh 9-7 | F13: S2-TMT- Kênh 9-8 | G13: 105.15303 | H13: 10.55134 | I13: 105.155 | J13: 10.5537 | K13: 320 | Q13: 1 | T13: Tuyến BTS CPH023 - Kênh 9 | U13: 1 | V13: OK | W13: Bổ sung hạ tầng đan xen tuyến hiện tại
A14: Dưới Bến Đò DT - PON Thị Đầy | B14: 9 | C14: Châu Phú | D14: CPH023 | E14: S2-TMT- Kênh 9-8 | F14: S2-TMT- Kênh 9-9 | G14: 105.155 | H14: 10.5537 | I14: 105.1556 | J14: 10.55443 | K14: 130 | Q14: 1 | T14: Tuyến BTS CPH023 - Kênh 9 | U14: 1 | V14: OK | W14: Bổ sung hạ tầng đan xen tuyến hiện tại
A15: Dưới Bến Đò DT - PON Thị Đầy | B15: 10 | C15: Châu Phú | D15: CPH023 | E15: S2-TMT- Kênh 9-9 | F15: S2-TMT- Kênh 9-10 | G15: 105.1556 | H15: 10.55443 | I15: 105.15669 | J15: 10.55567 | K15: 210 | N15: 1 | Q15: 1 | T15: Tuyến BTS CPH023 - Kênh 9 | U15: 1 | V15: OK | W15: Bổ sung hạ tầng đan xen tuyến hiện tại
A16: Dưới Bến Đò DT - PON Thị Đầy | B16: 11 | C16: Châu Phú | D16: CPH023 | E16: S2-TMT- Kênh 9-10 | F16: S2-TMT- Kênh 9-11 | G16: 105.15669 | H16: 10.55567 | I16: 105.15753 | J16: 10.5567 | K16: 160 | Q16: 1 | T16: Tuyến BTS CPH023 - Kênh 9 | U16: 1 | V16: OK | W16: Bổ sung hạ tầng đan xen tuyến hiện tại
A17: Trạm 024 - Tủ BS Bình | B17: 12 | C17: Châu Phú | D17: CPH023 | E17: S2-TMT- Kênh 9-11 | F17: S2-TMT- Kênh 9-12 | G17: 105.15753 | H17: 10.5567 | I17: 105.15908 | J17: 10.55846 | K17: 250 | Q17: 1 | T17: Tuyến BTS CPH023 - Kênh 9 | U17: 1 | V17: OK | W17: Bổ sung hạ tầng đan xen tuyến hiện tại
A18: Trạm 024 - Tủ BS Bình | B18: 13 | C18: Châu Phú | D18: CPH023 | E18: S2-TMT- Kênh 9-12 | F18: S2-TMT- Kênh 9-13 | G18: 105.15908 | H18: 10.55846 | I18: 105.15953 | J18: 10.55902 | K18: 250 | Q18: 1 | T18: Tuyến BTS CPH023 - Kênh 9 | U18: 1 | V18: OK | W18: Bổ sung hạ tầng đan xen tuyến hiện tại
A19: Trạm 024 - Tủ BS Bình | B19: 14 | C19: Châu Phú | D19: CPH023 | E19: S2-TMT- Kênh 9-13 | F19: S2-TMT- Kênh 9-14 | G19: 105.15953 | H19: 10.55902 | I19: 105.16173 | J19: 10.56161 | K19: 210 | N19: 1 | Q19: 1 | T19: Tuyến BTS CPH023 - Kênh 9 | U19: 1 | V19: OK | W19: Bổ sung hạ tầng đan xen tuyến hiện tại
A20: Trạm 024 - Tủ BS Bình | B20: 15 | C20: Châu Phú | D20: CPH023 | E20: S2-TMT- Kênh 9-14 | F20: S2-TMT- Kênh 9-15 | G20: 105.16173 | H20: 10.56161 | I20: 105.16269 | J20: 10.56272 | K20: 160 | Q20: 1 | T20: Tuyến BTS CPH023 - Kênh 9 | U20: 1 | V20: OK | W20: Bổ sung hạ tầng đan xen tuyến hiện tại
A21: Trạm 024 - Tủ BS Bình | B21: 16 | C21: Châu Phú | D21: CPH023 | E21: S2-TMT- Kênh 9-15 | F21: S2-TMT- Kênh 9-16 | G21: 105.16269 | H21: 10.56272 | I21: 105.16452 | J21: 10.56487 | K21: 250 | Q21: 1 | T21: Tuyến BTS CPH023 - Kênh 9 | U21: 1 | V21: OK | W21: Bổ sung hạ tầng đan xen tuyến hiện tại
A22: Trạm 024 - Tủ BS Bình | B22: 17 | C22: Châu Phú | D22: CPH020 | E22: Trạm CPH020 | F22: S2-20M- Cầu tre 1 | G22: 105.17131 | H22: 10.57141 | I22: 105.1706 | J22: 10.57201 | K22: 160 | Q22: 1 | R22: 1 | T22: Tuyến BTS CPH020 - Cầu tre | U22: 1 | V22: OK | W22: Bổ sung hạ tầng đan xen tuyến hiện tại
A23: Trạm 024 - Tủ BS Bình | B23: 18 | C23: Châu Phú | D23: CPH020 | E23: S2-20M- Cầu tre 1 | F23: S2-20M- Cầu tre 2 | G23: 105.1706 | H23: 10.57201 | I23: 105.17201 | J23: 10.57365 | K23: 250 | N23: 1 | Q23: 1 | T23: Tuyến BTS CPH020 - Cầu tre | U23: 1 | V23: OK | W23: Bổ sung hạ tầng đan xen tuyến hiện tại
A24: Trạm 024 - Tủ BS Bình | B24: 19 | C24: Châu Phú | D24: CPH020 | E24: S2-20M- Cầu tre 2 | F24: S2-20M- Cầu tre 3 | G24: 105.17201 | H24: 10.57365 | I24: 105.17332 | J24: 10.57506 | K24: 240 | Q24: 1 | T24: Tuyến BTS CPH020 - Cầu tre | U24: 1 | V24: OK | W24: Bổ sung hạ tầng đan xen tuyến hiện tại
A25: Trạm 024 - Tủ BS Bình | B25: 20 | C25: Châu Phú | D25: CPH020 | E25: S2-20M- Cầu tre 3 | F25: S2-20M- Cầu tre 4 | G25: 105.17332 | H25: 10.57506 | I25: 105.17438 | J25: 10.57641 | K25: 210 | Q25: 1 | T25: Tuyến BTS CPH020 - Cầu tre | U25: 1 | V25: OK | W25: Bổ sung hạ tầng đan xen tuyến hiện tại
A26: Trạm 024 - Tủ BS Bình | B26: 21 | C26: Châu Phú | D26: CPH020 | E26: S2-20M- Cầu tre 4 | F26: S2-20M- Cầu tre 5 | G26: 105.17438 | H26: 10.57641 | I26: 105.17543 | J26: 10.5776 | K26: 160 | Q26: 1 | T26: Tuyến BTS CPH020 - Cầu tre | U26: 1 | V26: OK | W26: Bổ sung hạ tầng đan xen tuyến hiện tại
A27: Trạm 024 - Tủ BS Bình | B27: 22 | C27: Châu Phú | D27: CPH020 | E27: S2-20M- Cầu tre 5 | F27: S2-20M- Cầu tre 6 | G27: 105.17543 | H27: 10.5776 | I27: 105.17715 | J27: 10.57967 | K27: 270 | N27: 1 | Q27: 1 | T27: Tuyến BTS CPH020 - Cầu tre | U27: 1 | V27: OK | W27: Bổ sung hạ tầng đan xen tuyến hiện tại
A28: Trạm 024 - Tủ BS Bình | B28: 23 | C28: Châu Phú | D28: CPH020 | E28: S2-20M- Cầu tre 6 | F28: S2-20M- Cầu tre 7 | G28: 105.17715 | H28: 10.57967 | I28: 105.17827 | J28: 10.58095 | K28: 210 | Q28: 1 | T28: Tuyến BTS CPH020 - Cầu tre | U28: 1 | V28: OK | W28: Bổ sung hạ tầng đan xen tuyến hiện tại
A29: Trạm 024 - Tủ BS Bình | B29: 24 | C29: Châu Phú | D29: CPH020 | E29: S2-20M- Cầu tre 7 | F29: S2-20M- Cầu tre 8 | G29: 105.17827 | H29: 10.58095 | I29: 105.17957 | J29: 10.5825 | K29: 240 | Q29: 1 | T29: Tuyến BTS CPH020 - Cầu tre | U29: 1 | V29: OK | W29: Bổ sung hạ tầng đan xen tuyến hiện tại
A30: Trạm 024 - Tủ BS Bình | B30: 25 | C30: Châu Phú | D30: CPH023 | E30: Trạm CPH023 | F30: S2-TMT-Anh Thanh 1 | G30: 105.14714 | H30: 10.54137 | I30: 105.14509 | J30: 10.54334 | K30: 320 | Q30: 1 | R30: 1 | T30: Tuyến BTS CPH023 - hướng nhà anh Thanh | U30: 1 | V30: OK | W30: Bổ sung hạ tầng đan xen tuyến hiện tại
A31: Trạm 024 - Tủ BS Bình | B31: 26 | C31: Châu Phú | D31: CPH023 | E31: S2-TMT-Anh Thanh 1 | F31: S2-TMT-Anh Thanh 2 | G31: 105.14509 | H31: 10.54334 | I31: 105.14578 | J31: 10.54425 | K31: 130 | N31: 1 | Q31: 1 | T31: Tuyến BTS CPH023 - hướng nhà anh Thanh | U31: 1 | V31: OK | W31: Bổ sung hạ tầng đan xen tuyến hiện tại
A32: Trạm 024 - Tủ BS Bình | B32: 27 | C32: Châu Phú | D32: CPH023 | E32: S2-TMT-Anh Thanh 2 | F32: S2-TMT-Anh Thanh 3 | G32: 105.14578 | H32: 10.54425 | I32: 105.14752 | J32: 10.54628 | K32: 240 | Q32: 1 | T32: Tuyến BTS CPH023 - hướng nhà anh Thanh | U32: 1 | V32: OK | W32: Bổ sung hạ tầng đan xen tuyến hiện tại
A33: Vĩnh Bình 1 - Vĩnh Bình 6 | B33: 28 | C33: Châu Phú | D33: CPH023 | E33: S2-TMT-Anh Thanh 3 | F33: S2-TMT-Anh Thanh 4 | G33: 105.14752 | H33: 10.54628 | I33: 105.14913 | J33: 10.54815 | K33: 240 | Q33: 1 | T33: Tuyến BTS CPH023 - hướng nhà anh Thanh | U33: 1 | V33: OK | W33: Bổ sung hạ tầng đan xen tuyến hiện tại
A34: Vĩnh Bình 1 - Vĩnh Bình 6 | B34: 29 | C34: Châu Phú | D34: CPH023 | E34: S2-TMT-Anh Thanh 4 | F34: S2-TMT-Anh Thanh 5 | G34: 105.14913 | H34: 10.54815 | I34: 105.15025 | J34: 10.54951 | K34: 210 | Q34: 1 | T34: Tuyến BTS CPH023 - hướng nhà anh Thanh | U34: 1 | V34: OK | W34: Bổ sung hạ tầng đan xen tuyến hiện tại
A35: Vĩnh Bình 1 - Vĩnh Bình 6 | B35: 30 | C35: Châu Phú | D35: CPH023 | E35: S2-TMT-Anh Thanh 5 | F35: S2-TMT-Anh Thanh 6 | G35: 105.15025 | H35: 10.54951 | I35: 105.15146 | J35: 10.55089 | K35: 210 | N35: 1 | Q35: 1 | T35: Tuyến BTS CPH023 - hướng nhà anh Thanh | U35: 1 | V35: OK | W35: Bổ sung hạ tầng đan xen tuyến hiện tại
A36: Vĩnh Bình 1 - Vĩnh Bình 6 | B36: 31 | C36: Châu Phú | D36: CPH023 | E36: S2-TMT-Anh Thanh 6 | F36: S2-TMT-Anh Thanh 7 | G36: 105.15146 | H36: 10.55089 | I36: 105.15308 | J36: 10.55275 | K36: 240 | Q36: 1 | T36: Tuyến BTS CPH023 - hướng nhà anh Thanh | U36: 1 | V36: OK | W36: Bổ sung hạ tầng đan xen tuyến hiện tại
A37: Vĩnh Bình 1 - Vĩnh Bình 6 | B37: 32 | C37: Châu Phú | D37: CPH023 | E37: S2-TMT-Anh Thanh 7 | F37: S2-TMT-Anh Thanh 8 | G37: 105.15308 | H37: 10.55275 | I37: 105.15601 | J37: 10.55623 | K37: 350 | Q37: 1 | T37: Tuyến BTS CPH023 - hướng nhà anh Thanh | U37: 1 | V37: OK | W37: Bổ sung hạ tầng đan xen tuyến hiện tại
A38: 007 - K2 Chủ Mỹ OLT - S2-007 - K2 Chủ Mỹ 4 Cuối | B38: 33 | C38: Châu Phú | D38: CPH023 | E38: TMT-Anh Thanh 1 | F38: S2-TMT-Anh Thanh 9 | G38: 105.14509 | H38: 10.54334 | I38: 105.14421 | J38: 10.54236 | K38: 160 | Q38: 1 | T38: Tuyến BTS CPH023 - hướng nhà anh Thanh | U38: 1 | V38: OK | W38: Bổ sung hạ tầng đan xen tuyến hiện tại
A39: 007 - K2 Chủ Mỹ OLT - S2-007 - K2 Chủ Mỹ 4 Cuối | B39: 34 | C39: Châu Phú | D39: CPH023 | E39: S2-TMT-Anh Thanh 9 | F39: S2-TMT-Anh Thanh 10 | G39: 105.14421 | H39: 10.54236 | I39: 105.1429 | J39: 10.54076 | K39: 210 | N39: 1 | Q39: 1 | T39: Tuyến BTS CPH023 - hướng nhà anh Thanh | U39: 1 | V39: OK | W39: Bổ sung hạ tầng đan xen tuyến hiện tại
A40: 007 - K2 Chủ Mỹ OLT - S2-007 - K2 Chủ Mỹ 4 Cuối | B40: 35 | C40: Châu Phú | D40: CPH023 | E40: S2-TMT-Anh Thanh 10 | F40: S2-TMT-Anh Thanh 11 | G40: 105.1429 | H40: 10.54076 | I40: 105.14144 | J40: 10.53911 | K40: 210 | Q40: 1 | T40: Tuyến BTS CPH023 - hướng nhà anh Thanh | U40: 1 | V40: OK | W40: Bổ sung hạ tầng đan xen tuyến hiện tại
A41: 007 - K2 Chủ Mỹ OLT - S2-007 - K2 Chủ Mỹ 4 Cuối | B41: 36 | C41: Châu Phú | D41: CPH023 | E41: S2-TMT-Anh Thanh 11 | F41: S2-TMT-Anh Thanh 12 | G41: 105.14144 | H41: 10.53911 | I41: 105.14016 | J41: 10.53769 | K41: 210 | Q41: 1 | T41: Tuyến BTS CPH023 - hướng nhà anh Thanh | U41: 1 | V41: OK | W41: Bổ sung hạ tầng đan xen tuyến hiện tại
...

Sheet PTN_OK
B1: VTAG - TỔNG HỢP NHU CẦU CÁP QUANG GPON 2026
B3: TỔNG CỘNG: | I3: TTVT PHÚ TÂN | K3: =SUMIF($C$6:$C$4299,"Phú Tân",K6:K4299) -> 10000 | L3: =SUMIF($C$6:$C$4299,"Phú Tân",L6:L4299) -> 0 | M3: =SUMIF($C$6:$C$4299,"Phú Tân",M6:M4299) -> 0 | N3: =SUMIF($C$6:$C$4299,"Phú Tân",N6:N4299) -> 18 | O3: =SUMIF($C$6:$C$4299,"Phú Tân",O6:O4299) -> 0 | P3: =SUMIF($C$6:$C$4299,"Phú Tân",P6:P4299) -> 0 | Q3: =SUMIF($C$6:$C$4299,"Phú Tân",Q6:Q4299) -> 61 | R3: =SUMIF($C$6:$C$4299,"Phú Tân",R6:R4299) -> 0
A4: TUYẾN TỔNG HỢP | B4: STT | C4: Đơn vị | D4: OLT | E4: ĐIỂM ĐẦU A | F4: ĐIỂM ĐẦU B | G4: Tọa độ A | I4: Tọa độ B | K4: Cáp quang 6FO(m) | L4: Cáp quang 12FO(m) | M4: Cáp quang 24FO(m) | N4: SP 1:4 | O4: SP 1: 8 (S1) | P4: SP 1: 8 (S2) | Q4: SP 1: 16 | R4: ODF | S4: Ghi chú | T4: Thông tin bên Biểu 3_MẠNg GPON | U4: Mức độ Ưu tiên từ 1-3 | V4: TTHT CHECK
G5: Long | H5: lat | I5: Long | J5: lat | K5: =SUBTOTAL(9,K6:K3929) -> 10000 | L5: =SUBTOTAL(9,L6:L3929) -> 0 | M5: =SUBTOTAL(9,M6:M3929) -> 0 | N5: =SUBTOTAL(9,N6:N3929) -> 18 | O5: =SUBTOTAL(9,O6:O3929) -> 0 | P5: =SUBTOTAL(9,P6:P3929) -> 0 | Q5: =SUBTOTAL(9,Q6:Q3929) -> 61 | R5: =SUBTOTAL(9,R6:R3929) -> 0 | V5: KẾT QUẢ | W5: LÍ DO
A6: 6FO hướng Vĩnh Hoà - S2-Trên cao tốc Kênh Ngang Huệ Đức | B6: 1 | C6: Phú Tân | D6: PTA024/24M | E6: AGG.PTN.024.OLT.ZT21.3.1.3_BTS PHP 02 | F6: AGG.PTN.024.OLT.ZT21.3.1.1 | G6: 105.15517 | H6: 10.7061 | I6: 105.15356 | J6: 10.7065 | K6: 200 | N6: 1 | Q6: 1 | S6: Nâng dung lượng + PTM | T6: Tuyến PTA024 hướng lên | U6: 1 | V6: OK | W6: Nâng cao năng lực vùng hiện hữu
A7: 6FO hướng Vĩnh Hoà - S2-Trên cao tốc Kênh Ngang Huệ Đức | B7: 2 | C7: Phú Tân | D7: PTA024/24M | E7: AGG.PTN.024.OLT.ZT21.3.1.1 | F7: AGG.PTN.024.OLT.ZT21.3.1.4_Lò sấy Châu Phong | G7: 105.15356 | H7: 10.7065 | I7: 105.15296 | J7: 10.70666 | K7: 100 | S7: Nâng dung lượng + PTM | T7: Tuyến PTA024 hướng lên | U7: 1 | V7: OK | W7: Nâng cao năng lực vùng hiện hữu
A8: 6FO hướng Vĩnh Hoà - S2-Trên cao tốc Kênh Ngang Huệ Đức | B8: 3 | C8: Phú Tân | D8: PTA024/24M | E8: AGG.PTN.024.OLT.ZT21.3.1.4_Lò sấy Châu Phong | F8: AGG.PTN.024.OLT.ZT21.3.1.2 | G8: 105.15296 | H8: 10.70666 | I8: 105.15175 | J8: 10.707 | K8: 170 | Q8: 1 | S8: Nâng dung lượng + PTM | T8: Tuyến PTA024 hướng lên | U8: 1 | V8: OK | W8: Nâng cao năng lực vùng hiện hữu
A9: 6FO hướng Vĩnh Hoà - S2-Trên cao tốc Kênh Ngang Huệ Đức | B9: 4 | C9: Phú Tân | D9: PTA024/24M | E9: AGG.PTN.024.OLT.ZT21.3.1.2 | F9: AGG.PTN.024.OLT.ZT21.3.2.2 | G9: 105.15175 | H9: 10.707 | I9: 105.15303 | J9: 10.70826 | K9: 500 | Q9: 1 | S9: Nâng dung lượng + PTM | T9: Tuyến PTA024 hướng lên | U9: 1 | V9: OK | W9: Nâng cao năng lực vùng hiện hữu
A10: ODF 6F0 CTH019 hướng Vĩnh Thành - S2-Kênh Ba Mạnh | B10: 5 | C10: Phú Tân | D10: PTA024/24M | E10: AGG.PTN.024.OLT.ZT21.3.2.2 | F10: AGG.PTN.024.OLT.ZT21.3.2.3_Cấp 2 PHP | G10: 105.15303 | H10: 10.70826 | I10: 105.15455 | J10: 10.70819 | K10: 200 | N10: 1 | S10: Nâng dung lượng + PTM | T10: Tuyến PTA024 hướng lên | U10: 1 | V10: OK | W10: Nâng cao năng lực vùng hiện hữu
A11: ODF 6F0 CTH019 hướng Vĩnh Thành - S2-Kênh Ba Mạnh | B11: 6 | C11: Phú Tân | D11: PTA024/24M | E11: AGG.PTN.024.OLT.ZT21.3.2.3_Cấp 2 PHP | F11: AGG.PTN.024.OLT.ZT21.3.2.4 | G11: 105.15455 | H11: 10.70819 | I11: 105.15522 | J11: 10.70809 | K11: 100 | Q11: 1 | S11: Nâng dung lượng + PTM | T11: Tuyến PTA024 hướng lên | U11: 1 | V11: OK | W11: Nâng cao năng lực vùng hiện hữu
A12: ODF 6F0 CTH019 hướng Vĩnh Thành - S2-Kênh Ba Mạnh | B12: 7 | C12: Phú Tân | D12: PTA024/24M | E12: AGG.PTN.024.OLT.ZT21.3.2.4 | F12: AGG.PTN.024.OLT.ZT21.3.2.1_Trương Tiểu học PHP | G12: 105.15522 | H12: 10.70809 | I12: 105.15567 | J12: 10.70793 | K12: 80 | S12: Nâng dung lượng + PTM | T12: Tuyến PTA024 hướng lên | U12: 1 | V12: OK | W12: Nâng cao năng lực vùng hiện hữu
A13: ODF 6F0 CTH019 hướng Vĩnh Thành - S2-Kênh Ba Mạnh | B13: 8 | C13: Phú Tân | D13: PTA024/24M | E13: AGG.PTN.024.OLT.ZT21.3.2.4 | F13: AGG.PTN.024.OLT.ZT21.3.3.4_Thu Ba | G13: 105.15522 | H13: 10.70809 | I13: 105.15522 | J13: 10.70861 | K13: 100 | Q13: 1 | S13: Nâng dung lượng + PTM | T13: Tuyến PTA024 hướng lên | U13: 1 | V13: OK | W13: Nâng cao năng lực vùng hiện hữu
A14: ODF 6F0 CTH019 hướng Vĩnh Thành - S2-Kênh Ba Mạnh | B14: 9 | C14: Phú Tân | D14: PTA024/24M | E14: AGG.PTN.024.OLT.ZT21.3.3.4_Thu Ba | F14: AGG.PTN.024.OLT.ZT21.3.3.1 | G14: 105.15522 | H14: 10.70861 | I14: 105.15375 | J14: 10.70874 | K14: 200 | N14: 1 | Q14: 1 | S14: Nâng dung lượng + PTM | T14: Tuyến PTA024 hướng lên | U14: 1 | V14: OK | W14: Nâng cao năng lực vùng hiện hữu
A15: ODF 6F0 CTH019 hướng Vĩnh Thành - S2-Kênh Ba Mạnh | B15: 10 | C15: Phú Tân | D15: PTA024/24M | E15: AGG.PTN.024.OLT.ZT21.3.3.4_Thu Ba | F15: AGG.PTN.024.OLT.ZT21.3.3.3 | G15: 105.15522 | H15: 10.70861 | I15: 105.15588 | J15: 10.70834 | K15: 100 | Q15: 1 | S15: Nâng dung lượng + PTM | T15: Tuyến PTA024 hướng lên | U15: 1 | V15: OK | W15: Nâng cao năng lực vùng hiện hữu
A16: ODF 6F0 CTH019 hướng Vĩnh Thành - S2-Kênh Ba Mạnh | B16: 11 | C16: Phú Tân | D16: PTA024/24M | E16: AGG.PTN.024.OLT.ZT21.3.3.3 | F16: AGG.PTN.024.OLT.ZT21.3.3.2_KDC Phú Hiệp (dưới | G16: 105.15588 | H16: 10.70384 | I16: 105.15631 | J16: 10.70819 | K16: 100 | S16: Nâng dung lượng + PTM | T16: Tuyến PTA024 hướng lên | U16: 1 | V16: OK | W16: Nâng cao năng lực vùng hiện hữu
A17: ODF 6F0 CTH019 hướng Vĩnh Thành - S2-Kênh Ba Mạnh | B17: 12 | C17: Phú Tân | D17: PTA024/24M | E17: AGG.PTN.024.OLT.ZT21.3.4.2_Căn nhà màu đỏ | F17: AGG.PTN.024.OLT.ZT21.3.4.3 | G17: 105.15597 | H17: 10.70592 | I17: 105.15691 | J17: 10.70571 | Q17: 1 | S17: Nâng dung lượng + PTM | T17: Tuyến PTA024 hướng xuống | U17: 1 | V17: OK | W17: Nâng cao năng lực vùng hiện hữu
A18: ODF 6F0 CTH019 hướng Vĩnh Thành - S2-Kênh Ba Mạnh | B18: 13 | C18: Phú Tân | D18: PTA024/24M | E18: AGG.PTN.024.OLT.ZT21.3.4.1_Điện cơ Tánh | F18: AGG.PTN.024.OLT.ZT21.3.4.4 | G18: 105.16008 | H18: 10.70495 | I18: 105.15895 | J18: 10.70521 | Q18: 1 | S18: Nâng dung lượng + PTM | T18: Tuyến PTA024 hướng xuống | U18: 1 | V18: OK | W18: Nâng cao năng lực vùng hiện hữu
A19: ODF 6F0 CTH019 hướng Vĩnh Thành - S2-Kênh Ba Mạnh | B19: 14 | C19: Phú Tân | D19: PTA024/24M | E19: AGG.PTN.024.OLT.ZT21.3.6.1_Cây Xăng Nhân Dung | F19: AGG.PTN.024.OLT.ZT21.3.6.4 | G19: 105.16392 | H19: 10.70526 | I19: 105.16513 | J19: 10.70506 | Q19: 1 | S19: Nâng dung lượng + PTM | T19: Tuyến PTA024 hướng xuống | U19: 1 | V19: OK | W19: Nâng cao năng lực vùng hiện hữu
A20: PTN.PLG.OLT.ZT11.1.11.2_Đường ra số 5 - Phong 1_1 | B20: 15 | C20: Phú Tân | D20: PTA024/24M | E20: AGG.PTN.024.OLT.ZT21.3.8.4_Vườn Mai | F20: AGG.PTN.024.OLT.ZT21.3.8.2 | G20: 105.16531 | H20: 10.70377 | I20: 105.16395 | J20: 10.70408 | Q20: 1 | S20: Nâng dung lượng + PTM | T20: Tuyến PTA024 hướng xuống | U20: 1 | V20: OK | W20: Nâng cao năng lực vùng hiện hữu
A21: PTN.PLG.OLT.ZT11.1.11.2_Đường ra số 5 - Phong 1_1 | B21: 16 | C21: Phú Tân | D21: PTA015/PLG | E21: PTN.PLG.OLT.ZT11.1.16.2_đường ra HLC | F21: Phong 2 | G21: 105.227827 | H21: 10.725088 | I21: 105.22198 | J21: 10.721094 | Q21: 1 | S21: Nâng dung lượng + PTM | T21: Tuyến PLG hướng HLC | U21: 1 | V21: OK | W21: Nâng cao năng lực vùng hiện hữu
A22: PTN.PLG.OLT.ZT11.1.8.1_Kho Phước Thành - CX Khánh Phương | B22: 17 | C22: Phú Tân | D22: PTA015/PLG | E22: PTN.PLG.OLT.ZT11.1.16.1_ranh PLG-HLC | F22: Phong 3 | G22: 105.216006 | H22: 10.717167 | I22: 105.21794 | J22: 10.713398 | K22: 500 | Q22: 1 | S22: Nâng dung lượng + PTM | T22: Tuyến PLG hướng HLC | U22: 1 | V22: OK | W22: Nâng cao năng lực vùng hiện hữu
A23: PTN.PLG.OLT.ZT11.1.8.1_Kho Phước Thành - CX Khánh Phương | B23: 18 | C23: Phú Tân | D23: PTA015/PLG | E23: PTN.PLG.OLT.ZT11.1.4.1_Thọ An | F23: PTN.PLG.OLT.ZT11.1.4.3_Trên Thọ An | G23: 105.238381 | H23: 10.713129 | I23: 105.23799 | J23: 10.714019 | K23: 150 | S23: Nâng dung lượng + PTM | T23: Tuyến Thọ An hướng lên | U23: 1 | V23: OK | W23: Nâng cao năng lực vùng hiện hữu
